Workbook
Name LISTA_D: DB!$AC$2:$AC$190
Name LISTA_P: DB!$AB$2:$AB$65
Name LISTA_A: DB!$AE$2:$AE$90
Name LISTA_C: DB!$AD$2:$AD$194

Sheet Guida
A1: FANTACALCIO CLASSIC - SERIE A 2026/27
A2: Listone, priorita, abbinamenti di calendario e foglio d'asta. Dati: Fantacalcio.it, aggiornati al 1 settembre 2026. Solo giocatori nelle rose ufficiali di Serie A.
A4: PARAMETRI DELLA LEGA - compila solo le celle gialle
A5: Budget per squadra (crediti) | B5: 500 | C5: Il monte crediti di ogni fantallenatore.
A6: Numero di squadre nella lega | B6: 10 | C6: Serve a sapere quanti giocatori vengono davvero assegnati.
A7: Giocatori per rosa | B7: =SUM(B11:B14) -> 25 | C7: 3 portieri + 8 difensori + 8 centrocampisti + 6 attaccanti.
A8: Crediti totali in gioco | B8: =B5*B6 -> 5000 | C8: Budget x numero squadre: la torta che vi dividete all'asta.
A10: Reparto | B10: Slot in rosa | C10: % del budget | D10: Crediti del reparto | E10: Giocatori assegnati nella lega | F10: Fattore prezzo (K)
A11: Portieri | B11: 3 | C11: 0.06 | D11: =ROUND($B$5*C11,0) -> 30 | E11: =$B$6*B11 -> 30 | F11: =IFERROR(D11*$B$6/SUMPRODUCT((Portieri!$AH$4:$AH$67<=E11)*(Portieri!$H$4:$H$67^$B$18)),0) -> 1.3619827
A12: Difensori | B12: 8 | C12: 0.15 | D12: =ROUND($B$5*C12,0) -> 75 | E12: =$B$6*B12 -> 80 | F12: =IFERROR(D12*$B$6/SUMPRODUCT((Difensori!$AH$4:$AH$192<=E12)*(Difensori!$H$4:$H$192^$B$18)),0) -> 1.2703247
A13: Centrocampisti | B13: 8 | C13: 0.29 | D13: =ROUND($B$5*C13,0) -> 145 | E13: =$B$6*B13 -> 80 | F13: =IFERROR(D13*$B$6/SUMPRODUCT((Centrocampisti!$AH$4:$AH$196<=E13)*(Centrocampisti!$H$4:$H$196^$B$18)),0) -> 1.8113619
A14: Attaccanti | B14: 6 | C14: 0.5 | D14: =ROUND($B$5*C14,0) -> 250 | E14: =$B$6*B14 -> 60 | F14: =IFERROR(D14*$B$6/SUMPRODUCT((Attaccanti!$AH$4:$AH$92<=E14)*(Attaccanti!$H$4:$H$92^$B$18)),0) -> 3.4056009
A15: Totale | B15: =SUM(B11:B14) -> 25 | C15: =SUM(C11:C14) -> 1 | D15: =SUM(D11:D14) -> 500 | E15: =SUM(E11:E14) -> 250
A17: CURVA DEI PREZZI
A18: Compressione della curva (0,5 - 1,0) | B18: 0.6 | C18: 1,00 = prezzi proporzionali al FVM (top carissimi). 0,50 = curva molto piatta. 0,60 e la taratura consigliata: il miglior attaccante vale circa il 26% del budget.
A19: Prezzo consigliato = | B19: FVM^compressione x K | C19: K e calcolato per reparto in modo che la somma dei prezzi consigliati usi esattamente i crediti del reparto.
A21: PESI DELL'INDICE DI PRIORITA (totale 100)
A22: Peso valore di mercato (FVM) | B22: 60 | C22: Quanto pesa la valutazione di mercato del giocatore.
A23: Peso rendimento (fantamedia ponderata) | B23: 25 | C23: Fantamedia 2025/26 corretta per le presenze.
A24: Peso rigorista | B24: 10 | C24: 1o rigorista = 1,00 | 2o = 0,60 | 3o = 0,35 | 4o = 0,20.
A25: Peso calci piazzati | B25: 5 | C25: 1o tiratore = 1,00 | 2o = 0,60 | 3o = 0,35.
A27: VALORI DI RIFERIMENTO (calcolati)
A28: FVM massimo - Portieri | B28: =MAX(Portieri!$H$4:$H$67) -> 85
A29: FVM massimo - Difensori | B29: =MAX(Difensori!$H$4:$H$192) -> 240
A30: FVM massimo - Centrocampisti | B30: =MAX(Centrocampisti!$H$4:$H$196) -> 245
A31: FVM massimo - Attaccanti | B31: =MAX(Attaccanti!$H$4:$H$92) -> 450
A34: COME SI USA
A35: 1. | B35: Fogli Portieri / Difensori / Centrocampisti / Attaccanti: il listone completo (587 giocatori), gia ordinato per priorita. Ogni foglio ha i filtri attivi sull'intestazione.
A36: 2. | B36: Cambia i parametri qui sopra (celle gialle): budget, numero squadre, percentuali di reparto, pesi e compressione. Tutti i prezzi consigliati e le priorita si ricalcolano.
A37: 3. | B37: Foglio Abbinamenti: la matrice del calendario 2026/27. Il numero dice quante volte due squadre giocano in trasferta nella stessa giornata: piu basso = si coprono meglio. Sotto trovi le migliori coppie e i migliori terzetti di portieri.
A38: 4. | B38: Foglio Asta: scegli i giocatori dai menu a tendina e scrivi il prezzo pagato. I crediti scalano riga per riga a partire da 500 e il controllo abbinamento portieri si aggiorna da solo.
A39: 5. | B39: Foglio Statistiche 25-26: i dati grezzi della scorsa stagione, filtrabili.
A41: LEGENDA COLORI
A42: Giallo | B42: Celle da compilare o parametri modificabili.
A43: Verde | B43: Situazione favorevole: buon affare, abbinamento ottimo, budget in linea, titolare.
A44: Rosso | B44: Attenzione: prezzo sopra il consigliato, abbinamento sfavorevole, budget sforato, riserva.
A45: Arancione | B45: Titolare sulla carta ma zero presenze nelle prime due giornate: rischia il posto. Nel foglio Asta segnala anche un giocatore inserito due volte.
A47: LA COLONNA NOTA (aggiornata al 01/09/2026, dopo 2 giornate)
A48: INFORTUNATO (lungo stop) | B48: Rientro previsto da ottobre in poi: all'asta vale molto meno del prezzo consigliato, oppure e' un investimento a scadenza.
A49: Infortunato | B49: Fuori adesso ma con rientro atteso entro settembre: si prende scontato.
...

Sheet Portieri
A1: PORTIERI - Listone Fantacalcio Classic 2026/27
A2: 64 giocatori, solo quelli presenti nelle rose ufficiali di Serie A 2026/27. Ordinati per indice di priorita. Colonna NOTA: infortuni, rischio titolarita e nuovi acquisti (dati al 01/09/2026, dopo 2 giornate).
A3: Prio | B3: Indice | C3: Giocatore | D3: Squadra | E3: Ruolo Mantra | F3: Qt.I | G3: Qt.A | H3: FVM | I3: Prezzo consigliato | J3: Prezzo max | K3: Fascia | L3: Gerarchia stimata | M3: NOTA | N3: Rigorista | O3: Calci piazzati | P3: PG 25/26 | Q3: MV 25/26 | R3: FM 25/26 | S3: Gol 25/26 | T3: Assist 25/26 | U3: Rig. segnati 25/26 | V3: Amm. 25/26 | W3: Esp. 25/26 | X3: PG 26/27 (su 2) | Y3: MV 26/27 | Z3: FM 26/27 | AA3: Gol 26/27 | AB3: Assist 26/27 | AC3: Squadra 25/26 | AD3: Nuovo/Trasf. | AE3: FM ponderata | AF3: Miglior abbinamento (calendario) | AG3: Trasferte in comune | AH3: Rank FVM di ruolo | AI3: Dettaglio infortunio / stato
A4: =RANK(B4,$B$4:$B$67) -> 1 | B4: =ROUND(Guida!$B$22*H4/Guida!$B$28+Guida!$B$23*MAX(0,MIN(1,(AE4-5.4)/1.6))+Guida!$B$24*0+Guida!$B$25*0,1) -> 60.8 | C4: Svilar | D4: Roma | E4: Portiere | F4: 18 | G4: 19 | H4: 85 | I4: =MAX(1,ROUND(H4^Guida!$B$18*Guida!$F$11,0)) -> 20 | J4: =MAX(2,ROUND(I4*1.2,0)) -> 24 | K4: =IF(I4>=60,"Top",IF(I4>=30,"1a fascia",IF(I4>=15,"2a fascia",IF(I4>=7,"3a fascia",IF(I4>=3,"4a fascia","Scommessa"))))) -> 2a fascia | L4: Titolare | M4: Titolare confermato (2/2) | N4: - | O4: - | P4: 38 | Q4: 6.26 | R4: 5.45 | S4: 0 | T4: 0 | U4: 0/0 | V4: 0 | W4: 0 | X4: 2 | Y4: 6.25 | Z4: 6.25 | AA4: 0 | AB4: 0 | AC4: Roma | AD4: No | AE4: =ROUND(IF(P4="",5.5,R4*MIN(1,P4/25)+5.5*(1-MIN(1,P4/25))),2) -> 5.45 | AF4: Meret (NAP) | AG4: 3 | AH4: =RANK(H4,$H$4:$H$67) -> 1
A5: =RANK(B5,$B$4:$B$67) -> 2 | B5: =ROUND(Guida!$B$22*H5/Guida!$B$28+Guida!$B$23*MAX(0,MIN(1,(AE5-5.4)/1.6))+Guida!$B$24*0+Guida!$B$25*0,1) -> 51 | C5: Vicario | D5: Juventus | E5: Portiere | F5: 16 | G5: 17 | H5: 70 | I5: =MAX(1,ROUND(H5^Guida!$B$18*Guida!$F$11,0)) -> 17 | J5: =MAX(2,ROUND(I5*1.2,0)) -> 20 | K5: =IF(I5>=60,"Top",IF(I5>=30,"1a fascia",IF(I5>=15,"2a fascia",IF(I5>=7,"3a fascia",IF(I5>=3,"4a fascia","Scommessa"))))) -> 2a fascia | L5: Titolare | M5: Nuovo - Titolare confermato (2/2) | N5: - | O5: - | X5: 2 | Y5: 6.25 | Z5: 6.25 | AA5: 0 | AB5: 0 | AC5: - | AD5: Si | AE5: =ROUND(IF(P5="",5.5,R5*MIN(1,P5/25)+5.5*(1-MIN(1,P5/25))),2) -> 5.5 | AF5: Svilar (ROM) | AG5: 6 | AH5: =RANK(H5,$H$4:$H$67) -> 2
A6: =RANK(B6,$B$4:$B$67) -> 3 | B6: =ROUND(Guida!$B$22*H6/Guida!$B$28+Guida!$B$23*MAX(0,MIN(1,(AE6-5.4)/1.6))+Guida!$B$24*0+Guida!$B$25*0,1) -> 48.6 | C6: Martinez Jo. | D6: Inter | E6: Portiere | F6: 17 | G6: 17 | H6: 68 | I6: =MAX(1,ROUND(H6^Guida!$B$18*Guida!$F$11,0)) -> 17 | J6: =MAX(2,ROUND(I6*1.2,0)) -> 20 | K6: =IF(I6>=60,"Top",IF(I6>=30,"1a fascia",IF(I6>=15,"2a fascia",IF(I6>=7,"3a fascia",IF(I6>=3,"4a fascia","Scommessa"))))) -> 2a fascia | L6: Titolare | M6: Titolare confermato (2/2) | N6: - | O6: - | P6: 5 | Q6: 6 | R6: 5.2 | S6: 0 | T6: 0 | U6: 0/0 | V6: 0 | W6: 0 | X6: 2 | Y6: 6 | Z6: 5.5 | AA6: 0 | AB6: 0 | AC6: Inter | AD6: No | AE6: =ROUND(IF(P6="",5.5,R6*MIN(1,P6/25)+5.5*(1-MIN(1,P6/25))),2) -> 5.44 | AF6: Maignan (MIL) | AG6: 0 | AH6: =RANK(H6,$H$4:$H$67) -> 3
A7: =RANK(B7,$B$4:$B$67) -> 4 | B7: =ROUND(Guida!$B$22*H7/Guida!$B$28+Guida!$B$23*MAX(0,MIN(1,(AE7-5.4)/1.6))+Guida!$B$24*0+Guida!$B$25*0,1) -> 41.6 | C7: Carnesecchi | D7: Atalanta | E7: Portiere | F7: 16 | G7: 17 | H7: 55 | I7: =MAX(1,ROUND(H7^Guida!$B$18*Guida!$F$11,0)) -> 15 | J7: =MAX(2,ROUND(I7*1.2,0)) -> 18 | K7: =IF(I7>=60,"Top",IF(I7>=30,"1a fascia",IF(I7>=15,"2a fascia",IF(I7>=7,"3a fascia",IF(I7>=3,"4a fascia","Scommessa"))))) -> 2a fascia | L7: Titolare | M7: Titolare confermato (2/2) | N7: - | O7: - | P7: 37 | Q7: 6.36 | R7: 5.58 | S7: 0 | T7: 0 | U7: 0/0 | V7: 0 | W7: 0 | X7: 2 | Y7: 6.75 | Z7: 6.75 | AA7: 0 | AB7: 1 | AC7: Atalanta | AD7: No | AE7: =ROUND(IF(P7="",5.5,R7*MIN(1,P7/25)+5.5*(1-MIN(1,P7/25))),2) -> 5.58 | AF7: Svilar (ROM) | AG7: 7 | AH7: =RANK(H7,$H$4:$H$67) -> 4
A8: =RANK(B8,$B$4:$B$67) -> 5 | B8: =ROUND(Guida!$B$22*H8/Guida!$B$28+Guida!$B$23*MAX(0,MIN(1,(AE8-5.4)/1.6))+Guida!$B$24*0+Guida!$B$25*0,1) -> 37 | C8: Maignan | D8: Milan | E8: Portiere | F8: 15 | G8: 15 | H8: 52 | I8: =MAX(1,ROUND(H8^Guida!$B$18*Guida!$F$11,0)) -> 15 | J8: =MAX(2,ROUND(I8*1.2,0)) -> 18 | K8: =IF(I8>=60,"Top",IF(I8>=30,"1a fascia",IF(I8>=15,"2a fascia",IF(I8>=7,"3a fascia",IF(I8>=3,"4a fascia","Scommessa"))))) -> 2a fascia | L8: Titolare | M8: Titolare confermato (2/2) | N8: - | O8: - | P8: 37 | Q8: 6.26 | R8: 5.42 | S8: 0 | T8: 0 | U8: 0/0 | V8: 4 | W8: 0 | X8: 2 | Y8: 6 | Z8: 5.5 | AA8: 0 | AB8: 0 | AC8: Milan | AD8: No | AE8: =ROUND(IF(P8="",5.5,R8*MIN(1,P8/25)+5.5*(1-MIN(1,P8/25))),2) -> 5.42 | AF8: Martinez Jo. (INT) | AG8: 0 | AH8: =RANK(H8,$H$4:$H$67) -> 5
A9: =RANK(B9,$B$4:$B$67) -> 6 | B9: =ROUND(Guida!$B$22*H9/Guida!$B$28+Guida!$B$23*MAX(0,MIN(1,(AE9-5.4)/1.6))+Guida!$B$24*0+Guida!$B$25*0,1) -> 35.3 | C9: Butez | D9: Como | E9: Portiere | F9: 16 | G9: 15 | H9: 50 | I9: =MAX(1,ROUND(H9^Guida!$B$18*Guida!$F$11,0)) -> 14 | J9: =MAX(2,ROUND(I9*1.2,0)) -> 17 | K9: =IF(I9>=60,"Top",IF(I9>=30,"1a fascia",IF(I9>=15,"2a fascia",IF(I9>=7,"3a fascia",IF(I9>=3,"4a fascia","Scommessa"))))) -> 3a fascia | L9: Titolare | M9: Titolare confermato (2/2) | N9: - | O9: - | P9: 38 | Q9: 6.07 | R9: 5.37 | S9: 0 | T9: 1 | U9: 0/0 | V9: 3 | W9: 0 | X9: 2 | Y9: 5.75 | Z9: 4.75 | AA9: 0 | AB9: 0 | AC9: Como | AD9: No | AE9: =ROUND(IF(P9="",5.5,R9*MIN(1,P9/25)+5.5*(1-MIN(1,P9/25))),2) -> 5.37 | AF9: De Gea (FIO) | AG9: 6 | AH9: =RANK(H9,$H$4:$H$67) -> 6
A10: =RANK(B10,$B$4:$B$67) -> 7 | B10: =ROUND(Guida!$B$22*H10/Guida!$B$28+Guida!$B$23*MAX(0,MIN(1,(AE10-5.4)/1.6))+Guida!$B$24*0+Guida!$B$25*0,1) -> 33.9 | C10: Meret | D10: Napoli | E10: Portiere | F10: 11 | G10: 11 | H10: 48 | I10: =MAX(1,ROUND(H10^Guida!$B$18*Guida!$F$11,0)) -> 14 | J10: =MAX(2,ROUND(I10*1.2,0)) -> 17 | K10: =IF(I10>=60,"Top",IF(I10>=30,"1a fascia",IF(I10>=15,"2a fascia",IF(I10>=7,"3a fascia",IF(I10>=3,"4a fascia","Scommessa"))))) -> 3a fascia | L10: Titolare | M10: Titolare confermato (2/2) | N10: - | O10: - | P10: 11 | Q10: 6.23 | R10: 5.18 | S10: 0 | T10: 1 | U10: 0/0 | V10: 1 | W10: 0 | X10: 2 | Y10: 6 | Z10: 5 | AA10: 0 | AB10: 0 | AC10: Napoli | AD10: No | AE10: =ROUND(IF(P10="",5.5,R10*MIN(1,P10/25)+5.5*(1-MIN(1,P10/25))),2) -> 5.36 | AF10: Svilar (ROM) | AG10: 3 | AH10: =RANK(H10,$H$4:$H$67) -> 7
A11: =RANK(B11,$B$4:$B$67) -> 8 | B11: =ROUND(Guida!$B$22*H11/Guida!$B$28+Guida!$B$23*MAX(0,MIN(1,(AE11-5.4)/1.6))+Guida!$B$24*0+Guida!$B$25*0,1) -> 27 | C11: Mandas | D11: Lazio | E11: Portiere | F11: 9 | G11: 10 | H11: 36 | I11: =MAX(1,ROUND(H11^Guida!$B$18*Guida!$F$11,0)) -> 12 | J11: =MAX(2,ROUND(I11*1.2,0)) -> 14 | K11: =IF(I11>=60,"Top",IF(I11>=30,"1a fascia",IF(I11>=15,"2a fascia",IF(I11>=7,"3a fascia",IF(I11>=3,"4a fascia","Scommessa"))))) -> 3a fascia | L11: Titolare | M11: Titolare confermato (2/2) | N11: - | O11: - | X11: 2 | Y11: 6.25 | Z11: 6.25 | AA11: 0 | AB11: 0 | AC11: Lazio | AD11: No | AE11: =ROUND(IF(P11="",5.5,R11*MIN(1,P11/25)+5.5*(1-MIN(1,P11/25))),2) -> 5.5 | AF11: Svilar (ROM) | AG11: 0 | AH11: =RANK(H11,$H$4:$H$67) -> 8
A12: =RANK(B12,$B$4:$B$67) -> 9 | B12: =ROUND(Guida!$B$22*H12/Guida!$B$28+Guida!$B$23*MAX(0,MIN(1,(AE12-5.4)/1.6))+Guida!$B$24*0+Guida!$B$25*0,1) -> 22.6 | C12: Skorupski | D12: Bologna | E12: Portiere | F12: 10 | G12: 10 | H12: 32 | I12: =MAX(1,ROUND(H12^Guida!$B$18*Guida!$F$11,0)) -> 11 | J12: =MAX(2,ROUND(I12*1.2,0)) -> 13 | K12: =IF(I12>=60,"Top",IF(I12>=30,"1a fascia",IF(I12>=15,"2a fascia",IF(I12>=7,"3a fascia",IF(I12>=3,"4a fascia","Scommessa"))))) -> 3a fascia | L12: Titolare | M12: Titolare confermato (2/2) | N12: - | O12: - | P12: 18 | Q12: 6.19 | R12: 5.28 | S12: 0 | T12: 0 | U12: 0/0 | V12: 1 | W12: 1 | X12: 2 | Y12: 5.5 | Z12: 4.5 | AA12: 0 | AB12: 0 | AC12: Bologna | AD12: No | AE12: =ROUND(IF(P12="",5.5,R12*MIN(1,P12/25)+5.5*(1-MIN(1,P12/25))),2) -> 5.34 | AF12: Carnesecchi (ATA) | AG12: 6 | AH12: =RANK(H12,$H$4:$H$67) -> 9
A13: =RANK(B13,$B$4:$B$67) -> 10 | B13: =ROUND(Guida!$B$22*H13/Guida!$B$28+Guida!$B$23*MAX(0,MIN(1,(AE13-5.4)/1.6))+Guida!$B$24*0+Guida!$B$25*0,1) -> 21.2 | C13: De Gea | D13: Fiorentina | E13: Portiere | F13: 13 | G13: 11 | H13: 30 | I13: =MAX(1,ROUND(H13^Guida!$B$18*Guida!$F$11,0)) -> 10 | J13: =MAX(2,ROUND(I13*1.2,0)) -> 12 | K13: =IF(I13>=60,"Top",IF(I13>=30,"1a fascia",IF(I13>=15,"2a fascia",IF(I13>=7,"3a fascia",IF(I13>=3,"4a fascia","Scommessa"))))) -> 3a fascia | L13: Titolare | M13: Titolare confermato (2/2) | N13: - | O13: - | P13: 37 | Q13: 6.24 | R13: 5 | S13: 0 | T13: 0 | U13: 0/0 | V13: 0 | W13: 0 | X13: 2 | Y13: 5.25 | Z13: 1.75 | AA13: 0 | AB13: 0 | AC13: Fiorentina | AD13: No | AE13: =ROUND(IF(P13="",5.5,R13*MIN(1,P13/25)+5.5*(1-MIN(1,P13/25))),2) -> 5 | AF13: Butez (COM) | AG13: 6 | AH13: =RANK(H13,$H$4:$H$67) -> 10
A14: =RANK(B14,$B$4:$B$67) -> 11 | B14: =ROUND(Guida!$B$22*H14/Guida!$B$28+Guida!$B$23*MAX(0,MIN(1,(AE14-5.4)/1.6))+Guida!$B$24*0+Guida!$B$25*0,1) -> 19.9 | C14: Perri | D14: Torino | E14: Portiere | F14: 9 | G14: 9 | H14: 26 | I14: =MAX(1,ROUND(H14^Guida!$B$18*Guida!$F$11,0)) -> 10 | J14: =MAX(2,ROUND(I14*1.2,0)) -> 12 | K14: =IF(I14>=60,"Top",IF(I14>=30,"1a fascia",IF(I14>=15,"2a fascia",IF(I14>=7,"3a fascia",IF(I14>=3,"4a fascia","Scommessa"))))) -> 3a fascia | L14: Titolare | M14: Nuovo - RISCHIA il posto (0/2) | N14: - | O14: - | X14: 0 | AC14: - | AD14: Si | AE14: =ROUND(IF(P14="",5.5,R14*MIN(1,P14/25)+5.5*(1-MIN(1,P14/25))),2) -> 5.5 | AF14: Vicario (JUV) | AG14: 0 | AH14: =RANK(H14,$H$4:$H$67) -> 12
A15: =RANK(B15,$B$4:$B$67) -> 12 | B15: =ROUND(Guida!$B$22*H15/Guida!$B$28+Guida!$B$23*MAX(0,MIN(1,(AE15-5.4)/1.6))+Guida!$B$24*0+Guida!$B$25*0,1) -> 19.8 | C15: Okoye | D15: Udinese | E15: Portiere | F15: 9 | G15: 9 | H15: 28 | I15: =MAX(1,ROUND(H15^Guida!$B$18*Guida!$F$11,0)) -> 10 | J15: =MAX(2,ROUND(I15*1.2,0)) -> 12 | K15: =IF(I15>=60,"Top",IF(I15>=30,"1a fascia",IF(I15>=15,"2a fascia",IF(I15>=7,"3a fascia",IF(I15>=3,"4a fascia","Scommessa"))))) -> 3a fascia | L15: Titolare | M15: Titolare confermato (2/2) | N15: - | O15: - | P15: 30 | Q15: 6.07 | R15: 5.08 | S15: 0 | T15: 1 | U15: 0/0 | V15: 1 | W15: 1 | X15: 2 | Y15: 6.25 | Z15: 4.75 | AA15: 0 | AB15: 0 | AC15: Udinese | AD15: No | AE15: =ROUND(IF(P15="",5.5,R15*MIN(1,P15/25)+5.5*(1-MIN(1,P15/25))),2) -> 5.08 | AF15: Maignan (MIL) | AG15: 7 | AH15: =RANK(H15,$H$4:$H$67) -> 11
A16: =RANK(B16,$B$4:$B$67) -> 13 | B16: =ROUND(Guida!$B$22*H16/Guida!$B$28+Guida!$B$23*MAX(0,MIN(1,(AE16-5.4)/1.6))+Guida!$B$24*0+Guida!$B$25*0,1) -> 19.2 | C16: Sanchez Ro. | D16: Como | E16: Portiere | F16: 8 | G16: 8 | H16: 25 | I16: =MAX(1,ROUND(H16^Guida!$B$18*Guida!$F$11,0)) -> 9 | J16: =MAX(2,ROUND(I16*1.2,0)) -> 11 | K16: =IF(I16>=60,"Top",IF(I16>=30,"1a fascia",IF(I16>=15,"2a fascia",IF(I16>=7,"3a fascia",IF(I16>=3,"4a fascia","Scommessa"))))) -> 3a fascia | L16: Ballottaggio | M16: Nuovo - In ballottaggio (0/2) | N16: - | O16: - | X16: 0 | AC16: - | AD16: Si | AE16: =ROUND(IF(P16="",5.5,R16*MIN(1,P16/25)+5.5*(1-MIN(1,P16/25))),2) -> 5.5 | AF16: De Gea (FIO) | AG16: 6 | AH16: =RANK(H16,$H$4:$H$67) -> 14
A17: =RANK(B17,$B$4:$B$67) -> 14 | B17: =ROUND(Guida!$B$22*H17/Guida!$B$28+Guida!$B$23*MAX(0,MIN(1,(AE17-5.4)/1.6))+Guida!$B$24*0+Guida!$B$25*0,1) -> 18.4 | C17: Falcone | D17: Lecce | E17: Portiere | F17: 8 | G17: 8 | H17: 26 | I17: =MAX(1,ROUND(H17^Guida!$B$18*Guida!$F$11,0)) -> 10 | J17: =MAX(2,ROUND(I17*1.2,0)) -> 12 | K17: =IF(I17>=60,"Top",IF(I17>=30,"1a fascia",IF(I17>=15,"2a fascia",IF(I17>=7,"3a fascia",IF(I17>=3,"4a fascia","Scommessa"))))) -> 3a fascia | L17: Titolare | M17: Titolare confermato (2/2) | N17: - | O17: - | P17: 38 | Q17: 6.41 | R17: 5.22 | S17: 0 | T17: 0 | U17: 0/0 | V17: 2 | W17: 0 | X17: 2 | Y17: 6.25 | Z17: 4.25 | AA17: 0 | AB17: 0 | AC17: Lecce | AD17: No | AE17: =ROUND(IF(P17="",5.5,R17*MIN(1,P17/25)+5.5*(1-MIN(1,P17/25))),2) -> 5.22 | AF17: Skorupski (BOL) | AG17: 6 | AH17: =RANK(H17,$H$4:$H$67) -> 12
A18: =RANK(B18,$B$4:$B$67) -> 15 | B18: =ROUND(Guida!$B$22*H18/Guida!$B$28+Guida!$B$23*MAX(0,MIN(1,(AE18-5.4)/1.6))+Guida!$B$24*0+Guida!$B$25*0,1) -> 17.6 | C18: Caprile | D18: Cagliari | E18: Portiere | F18: 9 | G18: 10 | H18: 25 | I18: =MAX(1,ROUND(H18^Guida!$B$18*Guida!$F$11,0)) -> 9 | J18: =MAX(2,ROUND(I18*1.2,0)) -> 11 | K18: =IF(I18>=60,"Top",IF(I18>=30,"1a fascia",IF(I18>=15,"2a fascia",IF(I18>=7,"3a fascia",IF(I18>=3,"4a fascia","Scommessa"))))) -> 3a fascia | L18: Titolare | M18: Titolare confermato (2/2) | N18: - | O18: - | P18: 38 | Q18: 6.29 | R18: 4.87 | S18: 0 | T18: 0 | U18: 0/0 | V18: 2 | W18: 0 | X18: 2 | Y18: 6.5 | Z18: 6 | AA18: 0 | AB18: 0 | AC18: Cagliari | AD18: No | AE18: =ROUND(IF(P18="",5.5,R18*MIN(1,P18/25)+5.5*(1-MIN(1,P18/25))),2) -> 4.87 | AF18: Carnesecchi (ATA) | AG18: 6 | AH18: =RANK(H18,$H$4:$H$67) -> 14
A19: =RANK(B19,$B$4:$B$67) -> 16 | B19: =ROUND(Guida!$B$22*H19/Guida!$B$28+Guida!$B$23*MAX(0,MIN(1,(AE19-5.4)/1.6))+Guida!$B$24*0+Guida!$B$25*0,1) -> 10.6 | C19: Bijlow | D19: Genoa | E19: Portiere | F19: 8 | G19: 8 | H19: 15 | I19: =MAX(1,ROUND(H19^Guida!$B$18*Guida!$F$11,0)) -> 7 | J19: =MAX(2,ROUND(I19*1.2,0)) -> 8 | K19: =IF(I19>=60,"Top",IF(I19>=30,"1a fascia",IF(I19>=15,"2a fascia",IF(I19>=7,"3a fascia",IF(I19>=3,"4a fascia","Scommessa"))))) -> 3a fascia | L19: Titolare | M19: Titolare confermato (2/2) | N19: - | O19: - | P19: 16 | Q19: 6.06 | R19: 4.78 | S19: 0 | T19: 0 | U19: 0/0 | V19: 1 | W19: 0 | X19: 2 | Y19: 5.5 | Z19: 4 | AA19: 0 | AB19: 0 | AC19: Genoa | AD19: No | AE19: =ROUND(IF(P19="",5.5,R19*MIN(1,P19/25)+5.5*(1-MIN(1,P19/25))),2) -> 5.04 | AF19: Maignan (MIL) | AG19: 7 | AH19: =RANK(H19,$H$4:$H$67) -> 16
A20: =RANK(B20,$B$4:$B$67) -> 16 | B20: =ROUND(Guida!$B$22*H20/Guida!$B$28+Guida!$B$23*MAX(0,MIN(1,(AE20-5.4)/1.6))+Guida!$B$24*0+Guida!$B$25*0,1) -> 10.6 | C20: Muric | D20: Sassuolo | E20: Portiere | F20: 7 | G20: 7 | H20: 15 | I20: =MAX(1,ROUND(H20^Guida!$B$18*Guida!$F$11,0)) -> 7 | J20: =MAX(2,ROUND(I20*1.2,0)) -> 8 | K20: =IF(I20>=60,"Top",IF(I20>=30,"1a fascia",IF(I20>=15,"2a fascia",IF(I20>=7,"3a fascia",IF(I20>=3,"4a fascia","Scommessa"))))) -> 3a fascia | L20: Titolare | M20: Titolare confermato (2/2) | N20: - | O20: - | P20: 32 | Q20: 6.08 | R20: 4.77 | S20: 0 | T20: 0 | U20: 0/0 | V20: 4 | W20: 0 | X20: 2 | Y20: 6.25 | Z20: 4.75 | AA20: 0 | AB20: 0 | AC20: Sassuolo | AD20: No | AE20: =ROUND(IF(P20="",5.5,R20*MIN(1,P20/25)+5.5*(1-MIN(1,P20/25))),2) -> 4.77 | AF20: Corvi (PAR) | AG20: 4 | AH20: =RANK(H20,$H$4:$H$67) -> 16
A21: =RANK(B21,$B$4:$B$67) -> 18 | B21: =ROUND(Guida!$B$22*H21/Guida!$B$28+Guida!$B$23*MAX(0,MIN(1,(AE21-5.4)/1.6))+Guida!$B$24*0+Guida!$B$25*0,1) -> 10 | C21: Palmisani | D21: Frosinone | E21: Portiere | F21: 4 | G21: 5 | H21: 12 | I21: =MAX(1,ROUND(H21^Guida!$B$18*Guida!$F$11,0)) -> 6 | J21: =MAX(2,ROUND(I21*1.2,0)) -> 7 | K21: =IF(I21>=60,"Top",IF(I21>=30,"1a fascia",IF(I21>=15,"2a fascia",IF(I21>=7,"3a fascia",IF(I21>=3,"4a fascia","Scommessa"))))) -> 4a fascia | L21: Titolare | M21: Nuovo - Titolare confermato (2/2) | N21: - | O21: - | X21: 2 | Y21: 6.25 | Z21: 5.75 | AA21: 0 | AB21: 0 | AC21: - | AD21: Si | AE21: =ROUND(IF(P21="",5.5,R21*MIN(1,P21/25)+5.5*(1-MIN(1,P21/25))),2) -> 5.5 | AF21: Butez (COM) | AG21: 6 | AH21: =RANK(H21,$H$4:$H$67) -> 18
A22: =RANK(B22,$B$4:$B$67) -> 19 | B22: =ROUND(Guida!$B$22*H22/Guida!$B$28+Guida!$B$23*MAX(0,MIN(1,(AE22-5.4)/1.6))+Guida!$B$24*0+Guida!$B$25*0,1) -> 9.3 | C22: Stankovic F. | D22: Venezia | E22: Portiere | F22: 6 | G22: 6 | H22: 11 | I22: =MAX(1,ROUND(H22^Guida!$B$18*Guida!$F$11,0)) -> 6 | J22: =MAX(2,ROUND(I22*1.2,0)) -> 7 | K22: =IF(I22>=60,"Top",IF(I22>=30,"1a fascia",IF(I22>=15,"2a fascia",IF(I22>=7,"3a fascia",IF(I22>=3,"4a fascia","Scommessa"))))) -> 4a fascia | L22: Titolare | M22: Nuovo - Titolare confermato (2/2) | N22: - | O22: - | X22: 2 | Y22: 6 | Z22: 4 | AA22: 0 | AB22: 0 | AC22: - | AD22: Si | AE22: =ROUND(IF(P22="",5.5,R22*MIN(1,P22/25)+5.5*(1-MIN(1,P22/25))),2) -> 5.5 | AF22: Caprile (CAG) | AG22: 6 | AH22: =RANK(H22,$H$4:$H$67) -> 19
A23: =RANK(B23,$B$4:$B$67) -> 20 | B23: =ROUND(Guida!$B$22*H23/Guida!$B$28+Guida!$B$23*MAX(0,MIN(1,(AE23-5.4)/1.6))+Guida!$B$24*0+Guida!$B$25*0,1) -> 8.6 | C23: Tornqvist | D23: Monza | E23: Portiere | F23: 1 | G23: 1 | H23: 10 | I23: =MAX(1,ROUND(H23^Guida!$B$18*Guida!$F$11,0)) -> 5 | J23: =MAX(2,ROUND(I23*1.2,0)) -> 6 | K23: =IF(I23>=60,"Top",IF(I23>=30,"1a fascia",IF(I23>=15,"2a fascia",IF(I23>=7,"3a fascia",IF(I23>=3,"4a fascia","Scommessa"))))) -> 4a fascia | L23: Ballottaggio | M23: Nuovo - In ballottaggio (0/2) | N23: - | O23: - | X23: 0 | AC23: - | AD23: Si | AE23: =ROUND(IF(P23="",5.5,R23*MIN(1,P23/25)+5.5*(1-MIN(1,P23/25))),2) -> 5.5 | AF23: Falcone (LEC) | AG23: 6 | AH23: =RANK(H23,$H$4:$H$67) -> 20
A24: =RANK(B24,$B$4:$B$67) -> 21 | B24: =ROUND(Guida!$B$22*H24/Guida!$B$28+Guida!$B$23*MAX(0,MIN(1,(AE24-5.4)/1.6))+Guida!$B$24*0+Guida!$B$25*0,1) -> 7.4 | C24: Milinkovic-Savic V. | D24: Napoli | E24: Portiere | F24: 5 | G24: 5 | H24: 5 | I24: =MAX(1,ROUND(H24^Guida!$B$18*Guida!$F$11,0)) -> 4 | J24: =MAX(2,ROUND(I24*1.2,0)) -> 5 | K24: =IF(I24>=60,"Top",IF(I24>=30,"1a fascia",IF(I24>=15,"2a fascia",IF(I24>=7,"3a fascia",IF(I24>=3,"4a fascia","Scommessa"))))) -> 4a fascia | L24: Ballottaggio | M24: In ballottaggio (0/2) | N24: - | O24: - | P24: 27 | Q24: 6.2 | R24: 5.65 | S24: 0 | T24: 0 | U24: 0/0 | V24: 0 | W24: 0 | X24: 0 | AC24: Napoli | AD24: No | AE24: =ROUND(IF(P24="",5.5,R24*MIN(1,P24/25)+5.5*(1-MIN(1,P24/25))),2) -> 5.65 | AF24: Skorupski (BOL) | AG24: 6 | AH24: =RANK(H24,$H$4:$H$67) -> 23
A25: =RANK(B25,$B$4:$B$67) -> 22 | B25: =ROUND(Guida!$B$22*H25/Guida!$B$28+Guida!$B$23*MAX(0,MIN(1,(AE25-5.4)/1.6))+Guida!$B$24*0+Guida!$B$25*0,1) -> 7.1 | C25: Corvi | D25: Parma | E25: Portiere | F25: 1 | G25: 2 | H25: 10 | I25: =MAX(1,ROUND(H25^Guida!$B$18*Guida!$F$11,0)) -> 5 | J25: =MAX(2,ROUND(I25*1.2,0)) -> 6 | K25: =IF(I25>=60,"Top",IF(I25>=30,"1a fascia",IF(I25>=15,"2a fascia",IF(I25>=7,"3a fascia",IF(I25>=3,"4a fascia","Scommessa"))))) -> 4a fascia | L25: Ballottaggio | M25: In ballottaggio (2/2) | N25: - | O25: - | P25: 17 | Q25: 6.18 | R25: 5.09 | S25: 0 | T25: 0 | U25: 0/0 | V25: 1 | W25: 0 | X25: 2 | Y25: 5.75 | Z25: 4.25 | AA25: 0 | AB25: 0 | AC25: Parma | AD25: No | AE25: =ROUND(IF(P25="",5.5,R25*MIN(1,P25/25)+5.5*(1-MIN(1,P25/25))),2) -> 5.22 | AF25: Falcone (LEC) | AG25: 4 | AH25: =RANK(H25,$H$4:$H$67) -> 20
A26: =RANK(B26,$B$4:$B$67) -> 23 | B26: =ROUND(Guida!$B$22*H26/Guida!$B$28+Guida!$B$23*MAX(0,MIN(1,(AE26-5.4)/1.6))+Guida!$B$24*0+Guida!$B$25*0,1) -> 6.5 | C26: Daffara | D26: Parma | E26: Portiere | F26: 7 | G26: 6 | H26: 7 | I26: =MAX(1,ROUND(H26^Guida!$B$18*Guida!$F$11,0)) -> 4 | J26: =MAX(2,ROUND(I26*1.2,0)) -> 5 | K26: =IF(I26>=60,"Top",IF(I26>=30,"1a fascia",IF(I26>=15,"2a fascia",IF(I26>=7,"3a fascia",IF(I26>=3,"4a fascia","Scommessa"))))) -> 4a fascia | L26: Titolare | M26: Nuovo - RISCHIA il posto (0/2) | N26: - | O26: - | X26: 0 | AC26: - | AD26: Si | AE26: =ROUND(IF(P26="",5.5,R26*MIN(1,P26/25)+5.5*(1-MIN(1,P26/25))),2) -> 5.5 | AF26: Falcone (LEC) | AG26: 4 | AH26: =RANK(H26,$H$4:$H$67) -> 22
A27: =RANK(B27,$B$4:$B$67) -> 24 | B27: =ROUND(Guida!$B$22*H27/Guida!$B$28+Guida!$B$23*MAX(0,MIN(1,(AE27-5.4)/1.6))+Guida!$B$24*0+Guida!$B$25*0,1) -> 5.1 | C27: Mascardi | D27: Torino | E27: Portiere | F27: 1 | G27: 1 | H27: 5 | I27: =MAX(1,ROUND(H27^Guida!$B$18*Guida!$F$11,0)) -> 4 | J27: =MAX(2,ROUND(I27*1.2,0)) -> 5 | K27: =IF(I27>=60,"Top",IF(I27>=30,"1a fascia",IF(I27>=15,"2a fascia",IF(I27>=7,"3a fascia",IF(I27>=3,"4a fascia","Scommessa"))))) -> 4a fascia | L27: Ballottaggio | M27: Nuovo - In ballottaggio (2/2) | N27: - | O27: - | X27: 2 | Y27: 5.75 | Z27: 3.75 | AA27: 0 | AB27: 0 | AC27: - | AD27: Si | AE27: =ROUND(IF(P27="",5.5,R27*MIN(1,P27/25)+5.5*(1-MIN(1,P27/25))),2) -> 5.5 | AF27: Falcone (LEC) | AG27: 7 | AH27: =RANK(H27,$H$4:$H$67) -> 23
A28: =RANK(B28,$B$4:$B$67) -> 24 | B28: =ROUND(Guida!$B$22*H28/Guida!$B$28+Guida!$B$23*MAX(0,MIN(1,(AE28-5.4)/1.6))+Guida!$B$24*0+Guida!$B$25*0,1) -> 5.1 | C28: Thiam | D28: Monza | E28: Portiere | F28: 5 | G28: 4 | H28: 5 | I28: =MAX(1,ROUND(H28^Guida!$B$18*Guida!$F$11,0)) -> 4 | J28: =MAX(2,ROUND(I28*1.2,0)) -> 5 | K28: =IF(I28>=60,"Top",IF(I28>=30,"1a fascia",IF(I28>=15,"2a fascia",IF(I28>=7,"3a fascia",IF(I28>=3,"4a fascia","Scommessa"))))) -> 4a fascia | L28: Titolare | M28: Nuovo - Rischia il posto (1/2) | N28: - | O28: - | X28: 1 | Y28: 4.5 | Z28: 1.5 | AA28: 0 | AB28: 0 | AC28: - | AD28: Si | AE28: =ROUND(IF(P28="",5.5,R28*MIN(1,P28/25)+5.5*(1-MIN(1,P28/25))),2) -> 5.5 | AF28: Falcone (LEC) | AG28: 6 | AH28: =RANK(H28,$H$4:$H$67) -> 23
A29: =RANK(B29,$B$4:$B$67) -> 26 | B29: =ROUND(Guida!$B$22*H29/Guida!$B$28+Guida!$B$23*MAX(0,MIN(1,(AE29-5.4)/1.6))+Guida!$B$24*0+Guida!$B$25*0,1) -> 3.5 | C29: Provedel | D29: Inter | E29: Portiere | F29: 2 | G29: 2 | H29: 5 | I29: =MAX(1,ROUND(H29^Guida!$B$18*Guida!$F$11,0)) -> 4 | J29: =MAX(2,ROUND(I29*1.2,0)) -> 5 | K29: =IF(I29>=60,"Top",IF(I29>=30,"1a fascia",IF(I29>=15,"2a fascia",IF(I29>=7,"3a fascia",IF(I29>=3,"4a fascia","Scommessa"))))) -> 4a fascia | L29: Ballottaggio | M29: Nuovo - In ballottaggio (0/2) | N29: - | O29: - | P29: 27 | Q29: 6.26 | R29: 5.35 | S29: 0 | T29: 0 | U29: 0/0 | V29: 1 | W29: 0 | X29: 0 | AC29: Lazio | AD29: Si | AE29: =ROUND(IF(P29="",5.5,R29*MIN(1,P29/25)+5.5*(1-MIN(1,P29/25))),2) -> 5.35 | AF29: Muric (SAS) | AG29: 4 | AH29: =RANK(H29,$H$4:$H$67) -> 23
A30: =RANK(B30,$B$4:$B$67) -> 27 | B30: =ROUND(Guida!$B$22*H30/Guida!$B$28+Guida!$B$23*MAX(0,MIN(1,(AE30-5.4)/1.6))+Guida!$B$24*0+Guida!$B$25*0,1) -> 2.9 | C30: Christensen O. | D30: Fiorentina | E30: Portiere | F30: 1 | G30: 1 | H30: 1 | I30: =MAX(1,ROUND(H30^Guida!$B$18*Guida!$F$11,0)) -> 1 | J30: =MAX(2,ROUND(I30*1.2,0)) -> 2 | K30: =IF(I30>=60,"Top",IF(I30>=30,"1a fascia",IF(I30>=15,"2a fascia",IF(I30>=7,"3a fascia",IF(I30>=3,"4a fascia","Scommessa"))))) -> Scommessa | L30: Ballottaggio | M30: In ballottaggio (0/2) | N30: - | O30: - | P30: 1 | Q30: 7.5 | R30: 6.5 | S30: 0 | T30: 0 | U30: 0/0 | V30: 0 | W30: 0 | X30: 0 | AC30: Fiorentina | AD30: No | AE30: =ROUND(IF(P30="",5.5,R30*MIN(1,P30/25)+5.5*(1-MIN(1,P30/25))),2) -> 5.54 | AF30: Caprile (CAG) | AG30: 6 | AH30: =RANK(H30,$H$4:$H$67) -> 27
A31: =RANK(B31,$B$4:$B$67) -> 27 | B31: =ROUND(Guida!$B$22*H31/Guida!$B$28+Guida!$B$23*MAX(0,MIN(1,(AE31-5.4)/1.6))+Guida!$B$24*0+Guida!$B$25*0,1) -> 2.9 | C31: Terracciano | D31: Milan | E31: Portiere | F31: 1 | G31: 1 | H31: 1 | I31: =MAX(1,ROUND(H31^Guida!$B$18*Guida!$F$11,0)) -> 1 | J31: =MAX(2,ROUND(I31*1.2,0)) -> 2 | K31: =IF(I31>=60,"Top",IF(I31>=30,"1a fascia",IF(I31>=15,"2a fascia",IF(I31>=7,"3a fascia",IF(I31>=3,"4a fascia","Scommessa"))))) -> Scommessa | L31: Ballottaggio | M31: In ballottaggio (0/2) | N31: - | O31: - | P31: 2 | Q31: 6 | R31: 6 | S31: 0 | T31: 0 | U31: 0/0 | V31: 0 | W31: 0 | X31: 0 | AC31: Milan | AD31: No | AE31: =ROUND(IF(P31="",5.5,R31*MIN(1,P31/25)+5.5*(1-MIN(1,P31/25))),2) -> 5.54 | AF31: Corvi (PAR) | AG31: 6 | AH31: =RANK(H31,$H$4:$H$67) -> 27
A32: =RANK(B32,$B$4:$B$67) -> 29 | B32: =ROUND(Guida!$B$22*H32/Guida!$B$28+Guida!$B$23*MAX(0,MIN(1,(AE32-5.4)/1.6))+Guida!$B$24*0+Guida!$B$25*0,1) -> 2.6 | C32: Pessina Mas. | D32: Bologna | E32: Portiere | F32: 1 | G32: 1 | H32: 1 | I32: =MAX(1,ROUND(H32^Guida!$B$18*Guida!$F$11,0)) -> 1 | J32: =MAX(2,ROUND(I32*1.2,0)) -> 2 | K32: =IF(I32>=60,"Top",IF(I32>=30,"1a fascia",IF(I32>=15,"2a fascia",IF(I32>=7,"3a fascia",IF(I32>=3,"4a fascia","Scommessa"))))) -> Scommessa | L32: Riserva | M32: Riserva (0/2) | N32: - | O32: - | P32: 4 | Q32: 6.12 | R32: 5.62 | S32: 0 | T32: 0 | U32: 0/0 | V32: 0 | W32: 0 | X32: 0 | AC32: Bologna | AD32: No | AE32: =ROUND(IF(P32="",5.5,R32*MIN(1,P32/25)+5.5*(1-MIN(1,P32/25))),2) -> 5.52 | AF32: Muric (SAS) | AG32: 6 | AH32: =RANK(H32,$H$4:$H$67) -> 27
A33: =RANK(B33,$B$4:$B$67) -> 30 | B33: =ROUND(Guida!$B$22*H33/Guida!$B$28+Guida!$B$23*MAX(0,MIN(1,(AE33-5.4)/1.6))+Guida!$B$24*0+Guida!$B$25*0,1) -> 2.3 | C33: Bleve | D33: Lecce | E33: Portiere | F33: 1 | G33: 1 | H33: 1 | I33: =MAX(1,ROUND(H33^Guida!$B$18*Guida!$F$11,0)) -> 1 | J33: =MAX(2,ROUND(I33*1.2,0)) -> 2 | K33: =IF(I33>=60,"Top",IF(I33>=30,"1a fascia",IF(I33>=15,"2a fascia",IF(I33>=7,"3a fascia",IF(I33>=3,"4a fascia","Scommessa"))))) -> Scommessa | L33: Riserva | M33: Nuovo - Riserva (0/2) | N33: - | O33: - | X33: 0 | AC33: - | AD33: Si | AE33: =ROUND(IF(P33="",5.5,R33*MIN(1,P33/25)+5.5*(1-MIN(1,P33/25))),2) -> 5.5 | AF33: Corvi (PAR) | AG33: 4 | AH33: =RANK(H33,$H$4:$H$67) -> 27
A34: =RANK(B34,$B$4:$B$67) -> 30 | B34: =ROUND(Guida!$B$22*H34/Guida!$B$28+Guida!$B$23*MAX(0,MIN(1,(AE34-5.4)/1.6))+Guida!$B$24*0+Guida!$B$25*0,1) -> 2.3 | C34: Contini | D34: Napoli | E34: Portiere | F34: 1 | G34: 1 | H34: 1 | I34: =MAX(1,ROUND(H34^Guida!$B$18*Guida!$F$11,0)) -> 1 | J34: =MAX(2,ROUND(I34*1.2,0)) -> 2 | K34: =IF(I34>=60,"Top",IF(I34>=30,"1a fascia",IF(I34>=15,"2a fascia",IF(I34>=7,"3a fascia",IF(I34>=3,"4a fascia","Scommessa"))))) -> Scommessa | L34: Riserva | M34: Riserva (0/2) | N34: - | O34: - | X34: 0 | AC34: Napoli | AD34: No | AE34: =ROUND(IF(P34="",5.5,R34*MIN(1,P34/25)+5.5*(1-MIN(1,P34/25))),2) -> 5.5 | AF34: Stankovic F. (VEN) | AG34: 7 | AH34: =RANK(H34,$H$4:$H$67) -> 27
A35: =RANK(B35,$B$4:$B$67) -> 30 | B35: =ROUND(Guida!$B$22*H35/Guida!$B$28+Guida!$B$23*MAX(0,MIN(1,(AE35-5.4)/1.6))+Guida!$B$24*0+Guida!$B$25*0,1) -> 2.3 | C35: De Marzi | D35: Roma | E35: Portiere | F35: 1 | G35: 1 | H35: 1 | I35: =MAX(1,ROUND(H35^Guida!$B$18*Guida!$F$11,0)) -> 1 | J35: =MAX(2,ROUND(I35*1.2,0)) -> 2 | K35: =IF(I35>=60,"Top",IF(I35>=30,"1a fascia",IF(I35>=15,"2a fascia",IF(I35>=7,"3a fascia",IF(I35>=3,"4a fascia","Scommessa"))))) -> Scommessa | L35: Ballottaggio | M35: Nuovo - In ballottaggio (0/2) | N35: - | O35: - | X35: 0 | AC35: - | AD35: Si | AE35: =ROUND(IF(P35="",5.5,R35*MIN(1,P35/25)+5.5*(1-MIN(1,P35/25))),2) -> 5.5 | AF35: Milinkovic-Savic V. (NAP) | AG35: 3 | AH35: =RANK(H35,$H$4:$H$67) -> 27
A36: =RANK(B36,$B$4:$B$67) -> 30 | B36: =ROUND(Guida!$B$22*H36/Guida!$B$28+Guida!$B$23*MAX(0,MIN(1,(AE36-5.4)/1.6))+Guida!$B$24*0+Guida!$B$25*0,1) -> 2.3 | C36: Desplanches | D36: Frosinone | E36: Portiere | F36: 2 | G36: 2 | H36: 1 | I36: =MAX(1,ROUND(H36^Guida!$B$18*Guida!$F$11,0)) -> 1 | J36: =MAX(2,ROUND(I36*1.2,0)) -> 2 | K36: =IF(I36>=60,"Top",IF(I36>=30,"1a fascia",IF(I36>=15,"2a fascia",IF(I36>=7,"3a fascia",IF(I36>=3,"4a fascia","Scommessa"))))) -> Scommessa | L36: Ballottaggio | M36: Nuovo - In ballottaggio (0/2) | N36: - | O36: - | X36: 0 | AC36: - | AD36: Si | AE36: =ROUND(IF(P36="",5.5,R36*MIN(1,P36/25)+5.5*(1-MIN(1,P36/25))),2) -> 5.5 | AF36: Milinkovic-Savic V. (NAP) | AG36: 6 | AH36: =RANK(H36,$H$4:$H$67) -> 27
A37: =RANK(B37,$B$4:$B$67) -> 30 | B37: =ROUND(Guida!$B$22*H37/Guida!$B$28+Guida!$B$23*MAX(0,MIN(1,(AE37-5.4)/1.6))+Guida!$B$24*0+Guida!$B$25*0,1) -> 2.3 | C37: Ghidotti | D37: Parma | E37: Portiere | F37: 1 | G37: 1 | H37: 1 | I37: =MAX(1,ROUND(H37^Guida!$B$18*Guida!$F$11,0)) -> 1 | J37: =MAX(2,ROUND(I37*1.2,0)) -> 2 | K37: =IF(I37>=60,"Top",IF(I37>=30,"1a fascia",IF(I37>=15,"2a fascia",IF(I37>=7,"3a fascia",IF(I37>=3,"4a fascia","Scommessa"))))) -> Scommessa | L37: Riserva | M37: Nuovo - Riserva (0/2) | N37: - | O37: - | X37: 0 | AC37: - | AD37: Si | AE37: =ROUND(IF(P37="",5.5,R37*MIN(1,P37/25)+5.5*(1-MIN(1,P37/25))),2) -> 5.5 | AF37: Mascardi (TOR) | AG37: 9 | AH37: =RANK(H37,$H$4:$H$67) -> 27
A38: =RANK(B38,$B$4:$B$67) -> 30 | B38: =ROUND(Guida!$B$22*H38/Guida!$B$28+Guida!$B$23*MAX(0,MIN(1,(AE38-5.4)/1.6))+Guida!$B$24*0+Guida!$B$25*0,1) -> 2.3 | C38: Gollini | D38: Roma | E38: Portiere | F38: 1 | G38: 1 | H38: 1 | I38: =MAX(1,ROUND(H38^Guida!$B$18*Guida!$F$11,0)) -> 1 | J38: =MAX(2,ROUND(I38*1.2,0)) -> 2 | K38: =IF(I38>=60,"Top",IF(I38>=30,"1a fascia",IF(I38>=15,"2a fascia",IF(I38>=7,"3a fascia",IF(I38>=3,"4a fascia","Scommessa"))))) -> Scommessa | L38: Riserva | M38: Riserva (0/2) | N38: - | O38: - | X38: 0 | AC38: Roma | AD38: No | AE38: =ROUND(IF(P38="",5.5,R38*MIN(1,P38/25)+5.5*(1-MIN(1,P38/25))),2) -> 5.5 | AF38: Daffara (PAR) | AG38: 12 | AH38: =RANK(H38,$H$4:$H$67) -> 27
A39: =RANK(B39,$B$4:$B$67) -> 30 | B39: =ROUND(Guida!$B$22*H39/Guida!$B$28+Guida!$B$23*MAX(0,MIN(1,(AE39-5.4)/1.6))+Guida!$B$24*0+Guida!$B$25*0,1) -> 2.3 | C39: Grabara | D39: Juventus | E39: Portiere | F39: 1 | G39: 1 | H39: 1 | I39: =MAX(1,ROUND(H39^Guida!$B$18*Guida!$F$11,0)) -> 1 | J39: =MAX(2,ROUND(I39*1.2,0)) -> 2 | K39: =IF(I39>=60,"Top",IF(I39>=30,"1a fascia",IF(I39>=15,"2a fascia",IF(I39>=7,"3a fascia",IF(I39>=3,"4a fascia","Scommessa"))))) -> Scommessa | L39: Riserva | M39: Nuovo - Riserva (0/2) | N39: - | O39: - | X39: 0 | AC39: - | AD39: Si | AE39: =ROUND(IF(P39="",5.5,R39*MIN(1,P39/25)+5.5*(1-MIN(1,P39/25))),2) -> 5.5 | AF39: Mascardi (TOR) | AG39: 0 | AH39: =RANK(H39,$H$4:$H$67) -> 27
A40: =RANK(B40,$B$4:$B$67) -> 30 | B40: =ROUND(Guida!$B$22*H40/Guida!$B$28+Guida!$B$23*MAX(0,MIN(1,(AE40-5.4)/1.6))+Guida!$B$24*0+Guida!$B$25*0,1) -> 2.3 | C40: Grandi | D40: Venezia | E40: Portiere | F40: 1 | G40: 1 | H40: 1 | I40: =MAX(1,ROUND(H40^Guida!$B$18*Guida!$F$11,0)) -> 1 | J40: =MAX(2,ROUND(I40*1.2,0)) -> 2 | K40: =IF(I40>=60,"Top",IF(I40>=30,"1a fascia",IF(I40>=15,"2a fascia",IF(I40>=7,"3a fascia",IF(I40>=3,"4a fascia","Scommessa"))))) -> Scommessa | L40: Ballottaggio | M40: Nuovo - In ballottaggio (0/2) | N40: - | O40: - | X40: 0 | AC40: - | AD40: Si | AE40: =ROUND(IF(P40="",5.5,R40*MIN(1,P40/25)+5.5*(1-MIN(1,P40/25))),2) -> 5.5 | AF40: Caprile (CAG) | AG40: 6 | AH40: =RANK(H40,$H$4:$H$67) -> 27
...

Sheet Difensori
A1: DIFENSORI - Listone Fantacalcio Classic 2026/27
A2: 189 giocatori, solo quelli presenti nelle rose ufficiali di Serie A 2026/27. Ordinati per indice di priorita. Colonna NOTA: infortuni, rischio titolarita e nuovi acquisti (dati al 01/09/2026, dopo 2 giornate).
A3: Prio | B3: Indice | C3: Giocatore | D3: Squadra | E3: Ruolo Mantra | F3: Qt.I | G3: Qt.A | H3: FVM | I3: Prezzo consigliato | J3: Prezzo max | K3: Fascia | L3: Gerarchia stimata | M3: NOTA | N3: Rigorista | O3: Calci piazzati | P3: PG 25/26 | Q3: MV 25/26 | R3: FM 25/26 | S3: Gol 25/26 | T3: Assist 25/26 | U3: Rig. segnati 25/26 | V3: Amm. 25/26 | W3: Esp. 25/26 | X3: PG 26/27 (su 2) | Y3: MV 26/27 | Z3: FM 26/27 | AA3: Gol 26/27 | AB3: Assist 26/27 | AC3: Squadra 25/26 | AD3: Nuovo/Trasf. | AE3: FM ponderata | AF3: Miglior abbinamento (calendario) | AG3: Trasferte in comune | AH3: Rank FVM di ruolo | AI3: Dettaglio infortunio / stato
A4: =RANK(B4,$B$4:$B$192) -> 1 | B4: =ROUND(Guida!$B$22*H4/Guida!$B$29+Guida!$B$23*MAX(0,MIN(1,(AE4-5.4)/1.6))+Guida!$B$24*0+Guida!$B$25*0.6,1) -> 88 | C4: Dimarco | D4: Inter | E4: Esterno basso / Esterno alto | F4: 32 | G4: 31 | H4: 240 | I4: =MAX(1,ROUND(H4^Guida!$B$18*Guida!$F$12,0)) -> 34 | J4: =MAX(2,ROUND(I4*1.2,0)) -> 41 | K4: =IF(I4>=60,"Top",IF(I4>=30,"1a fascia",IF(I4>=15,"2a fascia",IF(I4>=7,"3a fascia",IF(I4>=3,"4a fascia","Scommessa"))))) -> 1a fascia | L4: Titolare | M4: Titolare confermato (2/2) | N4: - | O4: 2o | P4: 35 | Q4: 6.6 | R4: 7.64 | S4: 7 | T4: 17 | U4: 0/0 | V4: 3 | W4: 0 | X4: 2 | Y4: 6.25 | Z4: 6.25 | AA4: 0 | AB4: 0 | AC4: Inter | AD4: No | AE4: =ROUND(IF(P4="",5.5,R4*MIN(1,P4/25)+5.5*(1-MIN(1,P4/25))),2) -> 7.64 | AF4: Pavlovic (MIL) | AG4: 0 | AH4: =RANK(H4,$H$4:$H$192) -> 1
A5: =RANK(B5,$B$4:$B$192) -> 2 | B5: =ROUND(Guida!$B$22*H5/Guida!$B$29+Guida!$B$23*MAX(0,MIN(1,(AE5-5.4)/1.6))+Guida!$B$24*0+Guida!$B$25*0,1) -> 38.5 | C5: Wesley | D5: Roma | E5: Esterno basso | F5: 17 | G5: 18 | H5: 87 | I5: =MAX(1,ROUND(H5^Guida!$B$18*Guida!$F$12,0)) -> 19 | J5: =MAX(2,ROUND(I5*1.2,0)) -> 23 | K5: =IF(I5>=60,"Top",IF(I5>=30,"1a fascia",IF(I5>=15,"2a fascia",IF(I5>=7,"3a fascia",IF(I5>=3,"4a fascia","Scommessa"))))) -> 2a fascia | L5: Titolare | M5: Titolare confermato (2/2) | N5: - | O5: - | P5: 30 | Q5: 6.12 | R5: 6.47 | S5: 5 | T5: 0 | U5: 0/0 | V5: 5 | W5: 2 | X5: 2 | Y5: 6.75 | Z5: 7.25 | AA5: 0 | AB5: 1 | AC5: Roma | AD5: No | AE5: =ROUND(IF(P5="",5.5,R5*MIN(1,P5/25)+5.5*(1-MIN(1,P5/25))),2) -> 6.47 | AF5: Rrahmani (NAP) | AG5: 3 | AH5: =RANK(H5,$H$4:$H$192) -> 2
A6: =RANK(B6,$B$4:$B$192) -> 3 | B6: =ROUND(Guida!$B$22*H6/Guida!$B$29+Guida!$B$23*MAX(0,MIN(1,(AE6-5.4)/1.6))+Guida!$B$24*0+Guida!$B$25*0,1) -> 37 | C6: Bremer | D6: Juventus | E6: Difensore centrale | F6: 15 | G6: 16 | H6: 60 | I6: =MAX(1,ROUND(H6^Guida!$B$18*Guida!$F$12,0)) -> 15 | J6: =MAX(2,ROUND(I6*1.2,0)) -> 18 | K6: =IF(I6>=60,"Top",IF(I6>=30,"1a fascia",IF(I6>=15,"2a fascia",IF(I6>=7,"3a fascia",IF(I6>=3,"4a fascia","Scommessa"))))) -> 2a fascia | L6: Titolare | M6: Titolare confermato (2/2) | N6: - | O6: - | P6: 26 | Q6: 6.33 | R6: 6.81 | S6: 4 | T6: 3 | U6: 0/0 | V6: 5 | W6: 0 | X6: 2 | Y6: 7 | Z6: 8.5 | AA6: 1 | AB6: 0 | AC6: Juventus | AD6: No | AE6: =ROUND(IF(P6="",5.5,R6*MIN(1,P6/25)+5.5*(1-MIN(1,P6/25))),2) -> 6.81 | AF6: Ostigard (GEN) | AG6: 5 | AH6: =RANK(H6,$H$4:$H$192) -> 4
A7: =RANK(B7,$B$4:$B$192) -> 4 | B7: =ROUND(Guida!$B$22*H7/Guida!$B$29+Guida!$B$23*MAX(0,MIN(1,(AE7-5.4)/1.6))+Guida!$B$24*0.6+Guida!$B$25*0,1) -> 33.8 | C7: Ostigard | D7: Genoa | E7: Difensore centrale | F7: 11 | G7: 11 | H7: 41 | I7: =MAX(1,ROUND(H7^Guida!$B$18*Guida!$F$12,0)) -> 12 | J7: =MAX(2,ROUND(I7*1.2,0)) -> 14 | K7: =IF(I7>=60,"Top",IF(I7>=30,"1a fascia",IF(I7>=15,"2a fascia",IF(I7>=7,"3a fascia",IF(I7>=3,"4a fascia","Scommessa"))))) -> 3a fascia | L7: Titolare | M7: Titolare confermato (2/2) | N7: 2o | O7: - | P7: 30 | Q7: 6.13 | R7: 6.52 | S7: 5 | T7: 0 | U7: 0/0 | V7: 7 | W7: 0 | X7: 2 | Y7: 6.5 | Z7: 6 | AA7: 0 | AB7: 0 | AC7: Genoa | AD7: No | AE7: =ROUND(IF(P7="",5.5,R7*MIN(1,P7/25)+5.5*(1-MIN(1,P7/25))),2) -> 6.52 | AF7: Bremer (JUV) | AG7: 5 | AH7: =RANK(H7,$H$4:$H$192) -> 13
A8: =RANK(B8,$B$4:$B$192) -> 5 | B8: =ROUND(Guida!$B$22*H8/Guida!$B$29+Guida!$B$23*MAX(0,MIN(1,(AE8-5.4)/1.6))+Guida!$B$24*0.6+Guida!$B$25*0,1) -> 33.1 | C8: Solet | D8: Udinese | E8: Difensore centrale | F8: 13 | G8: 13 | H8: 46 | I8: =MAX(1,ROUND(H8^Guida!$B$18*Guida!$F$12,0)) -> 13 | J8: =MAX(2,ROUND(I8*1.2,0)) -> 16 | K8: =IF(I8>=60,"Top",IF(I8>=30,"1a fascia",IF(I8>=15,"2a fascia",IF(I8>=7,"3a fascia",IF(I8>=3,"4a fascia","Scommessa"))))) -> 3a fascia | L8: Titolare | M8: Titolare confermato (2/2) | N8: 2o | O8: - | P8: 34 | Q8: 6.18 | R8: 6.4 | S8: 3 | T8: 1 | U8: 1/1 | V8: 1 | W8: 0 | X8: 2 | Y8: 6 | Z8: 6 | AA8: 0 | AB8: 0 | AC8: Udinese | AD8: No | AE8: =ROUND(IF(P8="",5.5,R8*MIN(1,P8/25)+5.5*(1-MIN(1,P8/25))),2) -> 6.4 | AF8: Ostigard (GEN) | AG8: 7 | AH8: =RANK(H8,$H$4:$H$192) -> 10
A9: =RANK(B9,$B$4:$B$192) -> 6 | B9: =ROUND(Guida!$B$22*H9/Guida!$B$29+Guida!$B$23*MAX(0,MIN(1,(AE9-5.4)/1.6))+Guida!$B$24*0+Guida!$B$25*0,1) -> 31.3 | C9: Pavlovic | D9: Milan | E9: Difensore centrale | F9: 14 | G9: 14 | H9: 49 | I9: =MAX(1,ROUND(H9^Guida!$B$18*Guida!$F$12,0)) -> 13 | J9: =MAX(2,ROUND(I9*1.2,0)) -> 16 | K9: =IF(I9>=60,"Top",IF(I9>=30,"1a fascia",IF(I9>=15,"2a fascia",IF(I9>=7,"3a fascia",IF(I9>=3,"4a fascia","Scommessa"))))) -> 3a fascia | L9: Titolare | M9: Titolare confermato (2/2) | N9: - | O9: - | P9: 34 | Q9: 6.24 | R9: 6.62 | S9: 5 | T9: 0 | U9: 0/0 | V9: 4 | W9: 0 | X9: 2 | Y9: 6.25 | Z9: 6 | AA9: 0 | AB9: 0 | AC9: Milan | AD9: No | AE9: =ROUND(IF(P9="",5.5,R9*MIN(1,P9/25)+5.5*(1-MIN(1,P9/25))),2) -> 6.62 | AF9: Dimarco (INT) | AG9: 0 | AH9: =RANK(H9,$H$4:$H$192) -> 7
A10: =RANK(B10,$B$4:$B$192) -> 7 | B10: =ROUND(Guida!$B$22*H10/Guida!$B$29+Guida!$B$23*MAX(0,MIN(1,(AE10-5.4)/1.6))+Guida!$B$24*0+Guida!$B$25*0,1) -> 29.8 | C10: Mancini | D10: Roma | E10: Difensore centrale | F10: 15 | G10: 16 | H10: 50 | I10: =MAX(1,ROUND(H10^Guida!$B$18*Guida!$F$12,0)) -> 13 | J10: =MAX(2,ROUND(I10*1.2,0)) -> 16 | K10: =IF(I10>=60,"Top",IF(I10>=30,"1a fascia",IF(I10>=15,"2a fascia",IF(I10>=7,"3a fascia",IF(I10>=3,"4a fascia","Scommessa"))))) -> 3a fascia | L10: Titolare | M10: Titolare confermato (2/2) | N10: - | O10: - | P10: 36 | Q10: 6.25 | R10: 6.51 | S10: 4 | T10: 2 | U10: 0/0 | V10: 9 | W10: 0 | X10: 2 | Y10: 6.5 | Z10: 7 | AA10: 0 | AB10: 1 | AC10: Roma | AD10: No | AE10: =ROUND(IF(P10="",5.5,R10*MIN(1,P10/25)+5.5*(1-MIN(1,P10/25))),2) -> 6.51 | AF10: Rrahmani (NAP) | AG10: 3 | AH10: =RANK(H10,$H$4:$H$192) -> 6
A11: =RANK(B11,$B$4:$B$192) -> 8 | B11: =ROUND(Guida!$B$22*H11/Guida!$B$29+Guida!$B$23*MAX(0,MIN(1,(AE11-5.4)/1.6))+Guida!$B$24*0+Guida!$B$25*0,1) -> 27.5 | C11: Akanji | D11: Inter | E11: Difensore centrale | F11: 16 | G11: 15 | H11: 47 | I11: =MAX(1,ROUND(H11^Guida!$B$18*Guida!$F$12,0)) -> 13 | J11: =MAX(2,ROUND(I11*1.2,0)) -> 16 | K11: =IF(I11>=60,"Top",IF(I11>=30,"1a fascia",IF(I11>=15,"2a fascia",IF(I11>=7,"3a fascia",IF(I11>=3,"4a fascia","Scommessa"))))) -> 3a fascia | L11: Titolare | M11: Titolare confermato (2/2) | N11: - | O11: - | P11: 32 | Q11: 6.28 | R11: 6.41 | S11: 2 | T11: 0 | U11: 0/0 | V11: 4 | W11: 0 | X11: 2 | Y11: 5.5 | Z11: 5.25 | AA11: 0 | AB11: 0 | AC11: Inter | AD11: No | AE11: =ROUND(IF(P11="",5.5,R11*MIN(1,P11/25)+5.5*(1-MIN(1,P11/25))),2) -> 6.41 | AF11: Pavlovic (MIL) | AG11: 0 | AH11: =RANK(H11,$H$4:$H$192) -> 8
A12: =RANK(B12,$B$4:$B$192) -> 9 | B12: =ROUND(Guida!$B$22*H12/Guida!$B$29+Guida!$B$23*MAX(0,MIN(1,(AE12-5.4)/1.6))+Guida!$B$24*0+Guida!$B$25*0,1) -> 27.1 | C12: Bisseck | D12: Inter | E12: Difensore centrale | F12: 11 | G12: 12 | H12: 36 | I12: =MAX(1,ROUND(H12^Guida!$B$18*Guida!$F$12,0)) -> 11 | J12: =MAX(2,ROUND(I12*1.2,0)) -> 13 | K12: =IF(I12>=60,"Top",IF(I12>=30,"1a fascia",IF(I12>=15,"2a fascia",IF(I12>=7,"3a fascia",IF(I12>=3,"4a fascia","Scommessa"))))) -> 3a fascia | L12: Titolare | M12: Titolare confermato (2/2) | N12: - | O12: - | P12: 23 | Q12: 6.22 | R12: 6.65 | S12: 3 | T12: 2 | U12: 0/0 | V12: 2 | W12: 0 | X12: 2 | Y12: 6.75 | Z12: 8.25 | AA12: 1 | AB12: 0 | AC12: Inter | AD12: No | AE12: =ROUND(IF(P12="",5.5,R12*MIN(1,P12/25)+5.5*(1-MIN(1,P12/25))),2) -> 6.56 | AF12: Pavlovic (MIL) | AG12: 0 | AH12: =RANK(H12,$H$4:$H$192) -> 16
A13: =RANK(B13,$B$4:$B$192) -> 10 | B13: =ROUND(Guida!$B$22*H13/Guida!$B$29+Guida!$B$23*MAX(0,MIN(1,(AE13-5.4)/1.6))+Guida!$B$24*0+Guida!$B$25*0,1) -> 26.8 | C13: Rrahmani | D13: Napoli | E13: Difensore centrale | F13: 14 | G13: 15 | H13: 51 | I13: =MAX(1,ROUND(H13^Guida!$B$18*Guida!$F$12,0)) -> 13 | J13: =MAX(2,ROUND(I13*1.2,0)) -> 16 | K13: =IF(I13>=60,"Top",IF(I13>=30,"1a fascia",IF(I13>=15,"2a fascia",IF(I13>=7,"3a fascia",IF(I13>=3,"4a fascia","Scommessa"))))) -> 3a fascia | L13: Titolare | M13: Titolare confermato (2/2) | N13: - | O13: - | P13: 21 | Q13: 6.24 | R13: 6.45 | S13: 2 | T13: 0 | U13: 0/0 | V13: 3 | W13: 0 | X13: 2 | Y13: 6.25 | Z13: 6.75 | AA13: 0 | AB13: 1 | AC13: Napoli | AD13: No | AE13: =ROUND(IF(P13="",5.5,R13*MIN(1,P13/25)+5.5*(1-MIN(1,P13/25))),2) -> 6.3 | AF13: Wesley (ROM) | AG13: 3 | AH13: =RANK(H13,$H$4:$H$192) -> 5
A14: =RANK(B14,$B$4:$B$192) -> 11 | B14: =ROUND(Guida!$B$22*H14/Guida!$B$29+Guida!$B$23*MAX(0,MIN(1,(AE14-5.4)/1.6))+Guida!$B$24*0+Guida!$B$25*0,1) -> 26.6 | C14: Kalulu | D14: Juventus | E14: Terzino destro / Difensore centrale | F14: 13 | G14: 14 | H14: 47 | I14: =MAX(1,ROUND(H14^Guida!$B$18*Guida!$F$12,0)) -> 13 | J14: =MAX(2,ROUND(I14*1.2,0)) -> 16 | K14: =IF(I14>=60,"Top",IF(I14>=30,"1a fascia",IF(I14>=15,"2a fascia",IF(I14>=7,"3a fascia",IF(I14>=3,"4a fascia","Scommessa"))))) -> 3a fascia | L14: Titolare | M14: Titolare confermato (2/2) | N14: - | O14: - | P14: 37 | Q14: 6.14 | R14: 6.35 | S14: 2 | T14: 4 | U14: 0/0 | V14: 2 | W14: 1 | X14: 2 | Y14: 6.5 | Z14: 6.5 | AA14: 0 | AB14: 0 | AC14: Juventus | AD14: No | AE14: =ROUND(IF(P14="",5.5,R14*MIN(1,P14/25)+5.5*(1-MIN(1,P14/25))),2) -> 6.35 | AF14: Belghali (TOR) | AG14: 0 | AH14: =RANK(H14,$H$4:$H$192) -> 8
A15: =RANK(B15,$B$4:$B$192) -> 12 | B15: =ROUND(Guida!$B$22*H15/Guida!$B$29+Guida!$B$23*MAX(0,MIN(1,(AE15-5.4)/1.6))+Guida!$B$24*0+Guida!$B$25*0,1) -> 25.4 | C15: Bastoni | D15: Inter | E15: Difensore centrale | F15: 14 | G15: 14 | H15: 43 | I15: =MAX(1,ROUND(H15^Guida!$B$18*Guida!$F$12,0)) -> 12 | J15: =MAX(2,ROUND(I15*1.2,0)) -> 14 | K15: =IF(I15>=60,"Top",IF(I15>=30,"1a fascia",IF(I15>=15,"2a fascia",IF(I15>=7,"3a fascia",IF(I15>=3,"4a fascia","Scommessa"))))) -> 3a fascia | L15: Titolare | M15: Titolare confermato (2/2) | N15: - | O15: - | P15: 28 | Q15: 6.2 | R15: 6.34 | S15: 1 | T15: 4 | U15: 0/0 | V15: 6 | W15: 0 | X15: 2 | Y15: 6.25 | Z15: 6.25 | AA15: 0 | AB15: 0 | AC15: Inter | AD15: No | AE15: =ROUND(IF(P15="",5.5,R15*MIN(1,P15/25)+5.5*(1-MIN(1,P15/25))),2) -> 6.34 | AF15: Pavlovic (MIL) | AG15: 0 | AH15: =RANK(H15,$H$4:$H$192) -> 11
A16: =RANK(B16,$B$4:$B$192) -> 13 | B16: =ROUND(Guida!$B$22*H16/Guida!$B$29+Guida!$B$23*MAX(0,MIN(1,(AE16-5.4)/1.6))+Guida!$B$24*0+Guida!$B$25*0,1) -> 24.9 | C16: N'Dicka | D16: Roma | E16: Difensore centrale | F16: 13 | G16: 13 | H16: 42 | I16: =MAX(1,ROUND(H16^Guida!$B$18*Guida!$F$12,0)) -> 12 | J16: =MAX(2,ROUND(I16*1.2,0)) -> 14 | K16: =IF(I16>=60,"Top",IF(I16>=30,"1a fascia",IF(I16>=15,"2a fascia",IF(I16>=7,"3a fascia",IF(I16>=3,"4a fascia","Scommessa"))))) -> 3a fascia | L16: Titolare | M16: In dubbio / da valutare - presenze finora: 1/2 | N16: - | O16: - | P16: 31 | Q16: 6.08 | R16: 6.32 | S16: 3 | T16: 1 | U16: 0/0 | V16: 5 | W16: 0 | X16: 1 | Y16: 6 | Z16: 6 | AA16: 0 | AB16: 0 | AC16: Roma | AD16: No | AE16: =ROUND(IF(P16="",5.5,R16*MIN(1,P16/25)+5.5*(1-MIN(1,P16/25))),2) -> 6.32 | AF16: Marusic (LAZ) | AG16: 0 | AH16: =RANK(H16,$H$4:$H$192) -> 12 | AI16: Fastidio all'adduttore nel riscaldamento a Lecce (31/8). A rischio con l'Atalanta.
A17: =RANK(B17,$B$4:$B$192) -> 14 | B17: =ROUND(Guida!$B$22*H17/Guida!$B$29+Guida!$B$23*MAX(0,MIN(1,(AE17-5.4)/1.6))+Guida!$B$24*0+Guida!$B$25*0,1) -> 24.3 | C17: Di Lorenzo | D17: Napoli | E17: Terzino destro / Esterno basso | F17: 12 | G17: 12 | H17: 39 | I17: =MAX(1,ROUND(H17^Guida!$B$18*Guida!$F$12,0)) -> 11 | J17: =MAX(2,ROUND(I17*1.2,0)) -> 13 | K17: =IF(I17>=60,"Top",IF(I17>=30,"1a fascia",IF(I17>=15,"2a fascia",IF(I17>=7,"3a fascia",IF(I17>=3,"4a fascia","Scommessa"))))) -> 3a fascia | L17: Titolare | M17: Titolare confermato (2/2) | N17: - | O17: - | P17: 26 | Q17: 6.08 | R17: 6.33 | S17: 2 | T17: 1 | U17: 0/0 | V17: 1 | W17: 0 | X17: 2 | Y17: 6 | Z17: 5.75 | AA17: 0 | AB17: 0 | AC17: Napoli | AD17: No | AE17: =ROUND(IF(P17="",5.5,R17*MIN(1,P17/25)+5.5*(1-MIN(1,P17/25))),2) -> 6.33 | AF17: Wesley (ROM) | AG17: 3 | AH17: =RANK(H17,$H$4:$H$192) -> 14
A18: =RANK(B18,$B$4:$B$192) -> 15 | B18: =ROUND(Guida!$B$22*H18/Guida!$B$29+Guida!$B$23*MAX(0,MIN(1,(AE18-5.4)/1.6))+Guida!$B$24*0+Guida!$B$25*0,1) -> 24.2 | C18: Spinazzola | D18: Napoli | E18: Terzino sinistro / Esterno basso | F18: 8 | G18: 8 | H18: 25 | I18: =MAX(1,ROUND(H18^Guida!$B$18*Guida!$F$12,0)) -> 9 | J18: =MAX(2,ROUND(I18*1.2,0)) -> 11 | K18: =IF(I18>=60,"Top",IF(I18>=30,"1a fascia",IF(I18>=15,"2a fascia",IF(I18>=7,"3a fascia",IF(I18>=3,"4a fascia","Scommessa"))))) -> 3a fascia | L18: Titolare | M18: Titolare confermato (2/2) | N18: - | O18: - | P18: 30 | Q18: 6.17 | R18: 6.55 | S18: 3 | T18: 3 | U18: 0/0 | V18: 1 | W18: 0 | X18: 2 | Y18: 5.75 | Z18: 5.75 | AA18: 0 | AB18: 0 | AC18: Napoli | AD18: No | AE18: =ROUND(IF(P18="",5.5,R18*MIN(1,P18/25)+5.5*(1-MIN(1,P18/25))),2) -> 6.55 | AF18: Wesley (ROM) | AG18: 3 | AH18: =RANK(H18,$H$4:$H$192) -> 24
A19: =RANK(B19,$B$4:$B$192) -> 16 | B19: =ROUND(Guida!$B$22*H19/Guida!$B$29+Guida!$B$23*MAX(0,MIN(1,(AE19-5.4)/1.6))+Guida!$B$24*0+Guida!$B$25*0,1) -> 22.6 | C19: Scalvini | D19: Atalanta | E19: Difensore centrale | F19: 10 | G19: 10 | H19: 28 | I19: =MAX(1,ROUND(H19^Guida!$B$18*Guida!$F$12,0)) -> 9 | J19: =MAX(2,ROUND(I19*1.2,0)) -> 11 | K19: =IF(I19>=60,"Top",IF(I19>=30,"1a fascia",IF(I19>=15,"2a fascia",IF(I19>=7,"3a fascia",IF(I19>=3,"4a fascia","Scommessa"))))) -> 3a fascia | L19: Titolare | M19: Titolare confermato (2/2) | N19: - | O19: - | P19: 24 | Q19: 6.06 | R19: 6.44 | S19: 3 | T19: 1 | U19: 0/0 | V19: 2 | W19: 0 | X19: 2 | Y19: 6 | Z19: 6 | AA19: 0 | AB19: 0 | AC19: Atalanta | AD19: No | AE19: =ROUND(IF(P19="",5.5,R19*MIN(1,P19/25)+5.5*(1-MIN(1,P19/25))),2) -> 6.4 | AF19: Mina (CAG) | AG19: 6 | AH19: =RANK(H19,$H$4:$H$192) -> 21
A20: =RANK(B20,$B$4:$B$192) -> 17 | B20: =ROUND(Guida!$B$22*H20/Guida!$B$29+Guida!$B$23*MAX(0,MIN(1,(AE20-5.4)/1.6))+Guida!$B$24*0+Guida!$B$25*0,1) -> 22.3 | C20: Hermoso | D20: Roma | E20: Difensore centrale | F20: 10 | G20: 11 | H20: 26 | I20: =MAX(1,ROUND(H20^Guida!$B$18*Guida!$F$12,0)) -> 9 | J20: =MAX(2,ROUND(I20*1.2,0)) -> 11 | K20: =IF(I20>=60,"Top",IF(I20>=30,"1a fascia",IF(I20>=15,"2a fascia",IF(I20>=7,"3a fascia",IF(I20>=3,"4a fascia","Scommessa"))))) -> 3a fascia | L20: Ballottaggio | M20: In ballottaggio (2/2) | N20: - | O20: - | P20: 27 | Q20: 6.17 | R20: 6.41 | S20: 3 | T20: 2 | U20: 0/0 | V20: 9 | W20: 0 | X20: 2 | Y20: 6.5 | Z20: 6.25 | AA20: 0 | AB20: 0 | AC20: Roma | AD20: No | AE20: =ROUND(IF(P20="",5.5,R20*MIN(1,P20/25)+5.5*(1-MIN(1,P20/25))),2) -> 6.41 | AF20: Marusic (LAZ) | AG20: 0 | AH20: =RANK(H20,$H$4:$H$192) -> 22
A21: =RANK(B21,$B$4:$B$192) -> 18 | B21: =ROUND(Guida!$B$22*H21/Guida!$B$29+Guida!$B$23*MAX(0,MIN(1,(AE21-5.4)/1.6))+Guida!$B$24*0.35+Guida!$B$25*0.35,1) -> 21.5 | C21: Valeri | D21: Parma | E21: Terzino sinistro / Esterno basso | F21: 8 | G21: 8 | H21: 22 | I21: =MAX(1,ROUND(H21^Guida!$B$18*Guida!$F$12,0)) -> 8 | J21: =MAX(2,ROUND(I21*1.2,0)) -> 10 | K21: =IF(I21>=60,"Top",IF(I21>=30,"1a fascia",IF(I21>=15,"2a fascia",IF(I21>=7,"3a fascia",IF(I21>=3,"4a fascia","Scommessa"))))) -> 3a fascia | L21: Titolare | M21: Titolare confermato (2/2) | N21: 3o | O21: 3o | P21: 34 | Q21: 6.06 | R21: 6.09 | S21: 0 | T21: 2 | U21: 0/0 | V21: 2 | W21: 0 | X21: 2 | Y21: 6 | Z21: 6 | AA21: 0 | AB21: 0 | AC21: Parma | AD21: No | AE21: =ROUND(IF(P21="",5.5,R21*MIN(1,P21/25)+5.5*(1-MIN(1,P21/25))),2) -> 6.09 | AF21: Tiago Gabriel (LEC) | AG21: 4 | AH21: =RANK(H21,$H$4:$H$192) -> 29
A22: =RANK(B22,$B$4:$B$192) -> 19 | B22: =ROUND(Guida!$B$22*H22/Guida!$B$29+Guida!$B$23*MAX(0,MIN(1,(AE22-5.4)/1.6))+Guida!$B$24*0+Guida!$B$25*0,1) -> 21.1 | C22: Molina N. | D22: Roma | E22: Esterno basso | F22: 18 | G22: 18 | H22: 78 | I22: =MAX(1,ROUND(H22^Guida!$B$18*Guida!$F$12,0)) -> 17 | J22: =MAX(2,ROUND(I22*1.2,0)) -> 20 | K22: =IF(I22>=60,"Top",IF(I22>=30,"1a fascia",IF(I22>=15,"2a fascia",IF(I22>=7,"3a fascia",IF(I22>=3,"4a fascia","Scommessa"))))) -> 2a fascia | L22: Titolare | M22: Nuovo - Rischia il posto (1/2) | N22: - | O22: - | X22: 1 | Y22: 6 | Z22: 6 | AA22: 0 | AB22: 0 | AC22: - | AD22: Si | AE22: =ROUND(IF(P22="",5.5,R22*MIN(1,P22/25)+5.5*(1-MIN(1,P22/25))),2) -> 5.5 | AF22: Marusic (LAZ) | AG22: 0 | AH22: =RANK(H22,$H$4:$H$192) -> 3
A23: =RANK(B23,$B$4:$B$192) -> 20 | B23: =ROUND(Guida!$B$22*H23/Guida!$B$29+Guida!$B$23*MAX(0,MIN(1,(AE23-5.4)/1.6))+Guida!$B$24*0+Guida!$B$25*0,1) -> 20.8 | C23: Kempf | D23: Como | E23: Difensore centrale | F23: 5 | G23: 5 | H23: 13 | I23: =MAX(1,ROUND(H23^Guida!$B$18*Guida!$F$12,0)) -> 6 | J23: =MAX(2,ROUND(I23*1.2,0)) -> 7 | K23: =IF(I23>=60,"Top",IF(I23>=30,"1a fascia",IF(I23>=15,"2a fascia",IF(I23>=7,"3a fascia",IF(I23>=3,"4a fascia","Scommessa"))))) -> 4a fascia | L23: Ballottaggio | M23: In ballottaggio (1/2) | N23: - | O23: - | P23: 29 | Q23: 6.12 | R23: 6.52 | S23: 4 | T23: 1 | U23: 0/0 | V23: 3 | W23: 0 | X23: 1 | Y23: 6.5 | Z23: 6.5 | AA23: 0 | AB23: 0 | AC23: Como | AD23: No | AE23: =ROUND(IF(P23="",5.5,R23*MIN(1,P23/25)+5.5*(1-MIN(1,P23/25))),2) -> 6.52 | AF23: Dodò (FIO) | AG23: 6 | AH23: =RANK(H23,$H$4:$H$192) -> 76
A24: =RANK(B24,$B$4:$B$192) -> 21 | B24: =ROUND(Guida!$B$22*H24/Guida!$B$29+Guida!$B$23*MAX(0,MIN(1,(AE24-5.4)/1.6))+Guida!$B$24*0.35+Guida!$B$25*0,1) -> 20.5 | C24: Mina | D24: Cagliari | E24: Difensore centrale | F24: 8 | G24: 7 | H24: 20 | I24: =MAX(1,ROUND(H24^Guida!$B$18*Guida!$F$12,0)) -> 8 | J24: =MAX(2,ROUND(I24*1.2,0)) -> 10 | K24: =IF(I24>=60,"Top",IF(I24>=30,"1a fascia",IF(I24>=15,"2a fascia",IF(I24>=7,"3a fascia",IF(I24>=3,"4a fascia","Scommessa"))))) -> 3a fascia | L24: Titolare | M24: In dubbio / da valutare - presenze finora: 0/2 | N24: 3o | O24: - | P24: 26 | Q24: 6 | R24: 6.17 | S24: 2 | T24: 1 | U24: 0/0 | V24: 3 | W24: 1 | X24: 0 | AC24: Cagliari | AD24: No | AE24: =ROUND(IF(P24="",5.5,R24*MIN(1,P24/25)+5.5*(1-MIN(1,P24/25))),2) -> 6.17 | AF24: Scalvini (ATA) | AG24: 6 | AH24: =RANK(H24,$H$4:$H$192) -> 33 | AI24: Affaticamento al polpaccio (29/8). Out con l'Inter, a rischio anche col Lecce.
A25: =RANK(B25,$B$4:$B$192) -> 22 | B25: =ROUND(Guida!$B$22*H25/Guida!$B$29+Guida!$B$23*MAX(0,MIN(1,(AE25-5.4)/1.6))+Guida!$B$24*0+Guida!$B$25*0,1) -> 19.3 | C25: Ramon | D25: Como | E25: Difensore centrale | F25: 10 | G25: 10 | H25: 31 | I25: =MAX(1,ROUND(H25^Guida!$B$18*Guida!$F$12,0)) -> 10 | J25: =MAX(2,ROUND(I25*1.2,0)) -> 12 | K25: =IF(I25>=60,"Top",IF(I25>=30,"1a fascia",IF(I25>=15,"2a fascia",IF(I25>=7,"3a fascia",IF(I25>=3,"4a fascia","Scommessa"))))) -> 3a fascia | L25: Titolare | M25: Titolare confermato (2/2) | N25: - | O25: - | P25: 32 | Q25: 6.16 | R25: 6.14 | S25: 2 | T25: 0 | U25: 0/0 | V25: 11 | W25: 1 | X25: 2 | Y25: 6 | Z25: 6 | AA25: 0 | AB25: 0 | AC25: Como | AD25: No | AE25: =ROUND(IF(P25="",5.5,R25*MIN(1,P25/25)+5.5*(1-MIN(1,P25/25))),2) -> 6.14 | AF25: Dodò (FIO) | AG25: 6 | AH25: =RANK(H25,$H$4:$H$192) -> 18
A26: =RANK(B26,$B$4:$B$192) -> 23 | B26: =ROUND(Guida!$B$22*H26/Guida!$B$29+Guida!$B$23*MAX(0,MIN(1,(AE26-5.4)/1.6))+Guida!$B$24*0+Guida!$B$25*0,1) -> 19.1 | C26: Vasquez | D26: Genoa | E26: Terzino sinistro / Difensore centrale | F26: 9 | G26: 9 | H26: 30 | I26: =MAX(1,ROUND(H26^Guida!$B$18*Guida!$F$12,0)) -> 10 | J26: =MAX(2,ROUND(I26*1.2,0)) -> 12 | K26: =IF(I26>=60,"Top",IF(I26>=30,"1a fascia",IF(I26>=15,"2a fascia",IF(I26>=7,"3a fascia",IF(I26>=3,"4a fascia","Scommessa"))))) -> 3a fascia | L26: Titolare | M26: Titolare confermato (2/2) | N26: - | O26: - | P26: 36 | Q26: 6.08 | R26: 6.14 | S26: 1 | T26: 0 | U26: 0/0 | V26: 2 | W26: 0 | X26: 2 | Y26: 5.75 | Z26: 5.75 | AA26: 0 | AB26: 0 | AC26: Genoa | AD26: No | AE26: =ROUND(IF(P26="",5.5,R26*MIN(1,P26/25)+5.5*(1-MIN(1,P26/25))),2) -> 6.14 | AF26: Bremer (JUV) | AG26: 5 | AH26: =RANK(H26,$H$4:$H$192) -> 20
A27: =RANK(B27,$B$4:$B$192) -> 24 | B27: =ROUND(Guida!$B$22*H27/Guida!$B$29+Guida!$B$23*MAX(0,MIN(1,(AE27-5.4)/1.6))+Guida!$B$24*0+Guida!$B$25*0,1) -> 18.8 | C27: Zappacosta | D27: Atalanta | E27: Terzino destro / Esterno basso | F27: 8 | G27: 8 | H27: 19 | I27: =MAX(1,ROUND(H27^Guida!$B$18*Guida!$F$12,0)) -> 7 | J27: =MAX(2,ROUND(I27*1.2,0)) -> 8 | K27: =IF(I27>=60,"Top",IF(I27>=30,"1a fascia",IF(I27>=15,"2a fascia",IF(I27>=7,"3a fascia",IF(I27>=3,"4a fascia","Scommessa"))))) -> 3a fascia | L27: Titolare | M27: Titolare confermato (2/2) | N27: - | O27: - | P27: 35 | Q27: 6.06 | R27: 6.3 | S27: 3 | T27: 1 | U27: 0/0 | V27: 3 | W27: 0 | X27: 2 | Y27: 6 | Z27: 6 | AA27: 0 | AB27: 0 | AC27: Atalanta | AD27: No | AE27: =ROUND(IF(P27="",5.5,R27*MIN(1,P27/25)+5.5*(1-MIN(1,P27/25))),2) -> 6.3 | AF27: Mina (CAG) | AG27: 6 | AH27: =RANK(H27,$H$4:$H$192) -> 44
A28: =RANK(B28,$B$4:$B$192) -> 25 | B28: =ROUND(Guida!$B$22*H28/Guida!$B$29+Guida!$B$23*MAX(0,MIN(1,(AE28-5.4)/1.6))+Guida!$B$24*0+Guida!$B$25*0.35,1) -> 18.4 | C28: Miranda J. | D28: Bologna | E28: Terzino sinistro / Esterno basso | F28: 8 | G28: 8 | H28: 23 | I28: =MAX(1,ROUND(H28^Guida!$B$18*Guida!$F$12,0)) -> 8 | J28: =MAX(2,ROUND(I28*1.2,0)) -> 10 | K28: =IF(I28>=60,"Top",IF(I28>=30,"1a fascia",IF(I28>=15,"2a fascia",IF(I28>=7,"3a fascia",IF(I28>=3,"4a fascia","Scommessa"))))) -> 3a fascia | L28: Titolare | M28: Rischia il posto (1/2) | N28: - | O28: 3o | P28: 31 | Q28: 6 | R28: 6.1 | S28: 1 | T28: 3 | U28: 0/0 | V28: 6 | W28: 0 | X28: 1 | Y28: 6 | Z28: 6 | AA28: 0 | AB28: 0 | AC28: Bologna | AD28: No | AE28: =ROUND(IF(P28="",5.5,R28*MIN(1,P28/25)+5.5*(1-MIN(1,P28/25))),2) -> 6.1 | AF28: Rrahmani (NAP) | AG28: 6 | AH28: =RANK(H28,$H$4:$H$192) -> 28
A29: =RANK(B29,$B$4:$B$192) -> 26 | B29: =ROUND(Guida!$B$22*H29/Guida!$B$29+Guida!$B$23*MAX(0,MIN(1,(AE29-5.4)/1.6))+Guida!$B$24*0+Guida!$B$25*0,1) -> 18.2 | C29: Valle | D29: Como | E29: Terzino sinistro / Esterno basso | F29: 6 | G29: 6 | H29: 21 | I29: =MAX(1,ROUND(H29^Guida!$B$18*Guida!$F$12,0)) -> 8 | J29: =MAX(2,ROUND(I29*1.2,0)) -> 10 | K29: =IF(I29>=60,"Top",IF(I29>=30,"1a fascia",IF(I29>=15,"2a fascia",IF(I29>=7,"3a fascia",IF(I29>=3,"4a fascia","Scommessa"))))) -> 3a fascia | L29: Titolare | M29: Titolare confermato (2/2) | N29: - | O29: - | P29: 26 | Q29: 6.06 | R29: 6.23 | S29: 1 | T29: 3 | U29: 0/0 | V29: 3 | W29: 0 | X29: 2 | Y29: 6 | Z29: 6 | AA29: 0 | AB29: 0 | AC29: Como | AD29: No | AE29: =ROUND(IF(P29="",5.5,R29*MIN(1,P29/25)+5.5*(1-MIN(1,P29/25))),2) -> 6.23 | AF29: Dodò (FIO) | AG29: 6 | AH29: =RANK(H29,$H$4:$H$192) -> 31
A30: =RANK(B30,$B$4:$B$192) -> 27 | B30: =ROUND(Guida!$B$22*H30/Guida!$B$29+Guida!$B$23*MAX(0,MIN(1,(AE30-5.4)/1.6))+Guida!$B$24*0+Guida!$B$25*0,1) -> 18 | C30: Kristensen T. | D30: Atalanta | E30: Terzino destro / Difensore centrale | F30: 7 | G30: 6 | H30: 20 | I30: =MAX(1,ROUND(H30^Guida!$B$18*Guida!$F$12,0)) -> 8 | J30: =MAX(2,ROUND(I30*1.2,0)) -> 10 | K30: =IF(I30>=60,"Top",IF(I30>=30,"1a fascia",IF(I30>=15,"2a fascia",IF(I30>=7,"3a fascia",IF(I30>=3,"4a fascia","Scommessa"))))) -> 3a fascia | L30: Titolare | M30: In dubbio / da valutare - Nuovo - presenze finora: 0/2 | N30: - | O30: - | P30: 28 | Q30: 5.98 | R30: 6.23 | S30: 3 | T30: 0 | U30: 0/0 | V30: 4 | W30: 0 | X30: 0 | AC30: Udinese | AD30: Si | AE30: =ROUND(IF(P30="",5.5,R30*MIN(1,P30/25)+5.5*(1-MIN(1,P30/25))),2) -> 6.23 | AF30: Mina (CAG) | AG30: 6 | AH30: =RANK(H30,$H$4:$H$192) -> 33 | AI30: Problema alla caviglia: saltate Sassuolo e Bologna, a rischio anche con la Roma.
A31: =RANK(B31,$B$4:$B$192) -> 28 | B31: =ROUND(Guida!$B$22*H31/Guida!$B$29+Guida!$B$23*MAX(0,MIN(1,(AE31-5.4)/1.6))+Guida!$B$24*0+Guida!$B$25*0,1) -> 17.9 | C31: Vojvoda | D31: Udinese | E31: Terzino destro / Esterno basso | F31: 8 | G31: 9 | H31: 19 | I31: =MAX(1,ROUND(H31^Guida!$B$18*Guida!$F$12,0)) -> 7 | J31: =MAX(2,ROUND(I31*1.2,0)) -> 8 | K31: =IF(I31>=60,"Top",IF(I31>=30,"1a fascia",IF(I31>=15,"2a fascia",IF(I31>=7,"3a fascia",IF(I31>=3,"4a fascia","Scommessa"))))) -> 3a fascia | L31: Titolare | M31: Nuovo - Titolare confermato (2/2) | N31: - | O31: - | P31: 27 | Q31: 6.02 | R31: 6.24 | S31: 2 | T31: 1 | U31: 0/0 | V31: 2 | W31: 0 | X31: 2 | Y31: 6.5 | Z31: 6.5 | AA31: 0 | AB31: 0 | AC31: Como | AD31: Si | AE31: =ROUND(IF(P31="",5.5,R31*MIN(1,P31/25)+5.5*(1-MIN(1,P31/25))),2) -> 6.24 | AF31: Ostigard (GEN) | AG31: 7 | AH31: =RANK(H31,$H$4:$H$192) -> 44
